Workbook

Sheet READ ME
A1: New Excel Bidding Spreadsheet: How It Works
A2: Rebuilt from 'Template-Empty - WORK IN PROGRESS.xlsm'. Full transparent cost first, margin added on top.
B4: FLOW
B5: 1. INPUTS | C5: Project info, durations, PST, consumables, contingency, target margin per division, levels, your typical COGS %.
B6: 2. LABOUR RATES | C6: Crew mix per trade (same layout as the original PRJ INFO rates block), shown beside Knowify actual rates and mix.
B7: 3. PLUMBING EST / HVAC EST | C7: One row per item: Qty x Material $/unit and Qty x Hrs/unit. Same columns on both sheets so HVAC ties back exactly like Plumbing.
B8: 4. SUBS & GC | C8: Subtrade quotes and general conditions. Allocate by % to each division, or leave % blank to auto-split by direct cost.
B9: 5. BID SUMMARY | C9: Cost by type and division, then margin. COGS mix vs your Knowify job and vs your typical %. Holds every tie-out check.
B10: 6. BUDGET | C10: Cost budget per division and phase. Phases match Knowify, so the field budget and the actuals line up.
B11: 7. SCHEDULE OF VALUES | C11: Contract split into Knowify-style lines (e.g. 'P - BLDG A - L1 Plumbing Rough-in (Labour)'), with the Knowify cost budget for each line.
B12: 8. KNOWIFY PHASES / TIME | C12: Paste the 'Actual vs Budget - Phases' and 'Time' sheets from a Knowify Job Summary export, cell A1, exactly as exported.
B13: 9. KNOWIFY REVIEW | C13: Reads the two paste tabs: margin after overhead, cost mix, actual crew rates and mix, and how each phase ran vs its budget.
B14: 10. AUDIT NOTES | C14: Formula problems found in the original template, decisions made, and open questions.
B16: COLOUR LEGEND
B17: Blue text, light yellow fill | C17: Input. Type here.
B18: Bright yellow fill | C18: Key assumption. Review on every bid.
B19: Black text | C19: Formula. Do not type over.
B20: Green text | C20: Link from another tab.
B22: MARGIN vs MARKUP
C23: This workbook prices with MARGIN: Contract = Total Cost / (1 - Margin %).
C24: Example: cost $100,000 at 15% margin = $117,647 contract, $17,647 gross profit (17.6% markup).
C25: The original template used 15% MARKUP: $100,000 x 1.15 = $115,000, which is only a 13.0% margin.
B27: PHASES (match Knowify)
C28: Tag each estimate row with the phase the WORK happens in. Rough-in and finishing rows carry both labour and material.
C29: Labour on 03 Rough-in and 04 Finishing is split by level on the SOV; their material rolls into 05 Material Supply automatically,
C30: the same way Knowify jobs are set up (level lines are labour only, material supply is its own line).
B32: UPDATING KNOWIFY DATA
C33: 1. In Knowify, open the job > Summary > Project Summary report and download the Excel file.
C34: 2. In that file, select the used cells of 'Actual vs Budget - Phases' (A1 to column V, last row). Copy.
C35: 3. Paste into cell A1 of KNOWIFY PHASES (clear old data first). Do the same for the 'Time' sheet into KNOWIFY TIME.
C36: 4. On KNOWIFY REVIEW, type the job name, contract (Total Amount) and committed cost from the export's Summary sheet.
C37: 5. If a role or phase shows 'Unmapped', add it to the mapping tables on the right of KNOWIFY REVIEW.

Sheet INPUTS
A1: INPUTS
A2: Blue cells are inputs. Bright yellow = key assumption to review on every bid.
B3: PROJECT INFORMATION
B4: Project Name
B5: Quote Number
B6: Project Type | C6: Multi-Family
B7: Owner
B8: General Contractor
B9: Architect
B10: Mech. Engineer
B11: Site Address | C11: 2650 East 41st Ave
B12: City | C12: Vancouver
B13: Proposal Date
B14: Proposal Rev
B15: Prepared By | C15: Paris Mechanical Ltd
B16: Drawings | C16: Issued For Tender
B17: Gross Floor Area (sq ft)
B18: Number of Units | C18: =D64 -> 123
B20: KEY ASSUMPTIONS
B21: P&H project duration (months) | C21: 24 | G21: From original PRJ INFO H34.
B22: HVAC project duration (months) | C22: 24 | G22: From original PRJ INFO H43.
B23: PST on materials | C23: 0.07 | G23: BC PST 7%. From original PRJ INFO H52. Applied to material rows marked Y.
B24: GST (shown on proposal only, not a cost) | C24: 0.05 | G24: From original PRJ INFO H51. GST is recoverable, so it is not in cost.
B25: Consumables (% of material) | C25: 0.02 | G25: Original used 2% of material (P&H SUMMARY H46, HVAC SUMMARY D30).
B26: Contingency (% of direct cost) | C26: 0 | G26: Optional risk allowance. Kept as its own line so it stays visible.
B27: Warranty reserve (% of fixture & equipment supply) | C27: 0.02 | G27: Original: 2 years x 1% of equipment+fixtures (PRJ SUMMARY rows 75-78).
B28: Contract rounding (round up to nearest $) | C28: 100 | G28: Original rounded each division up to the nearest $100.
B29: Holdback (BC Builders Lien Act) | C29: 0.1 | G29: Used on the SOV for progress billing.
B31: TARGET MARGIN BY DIVISION
B32: Division | C32: Code | D32: Target Margin % | E32: Equivalent Markup % | F32: Crew
B33: Plumbing | C33: P | D33: 0.15 | E33: =IFERROR(D33/(1-D33),0) -> 0.17647059 | F33: P&H | G33: Margin = profit / contract. 15% is a placeholder: set your real target.
B34: Hydronic | C34: H | D34: 0.15 | E34: =IFERROR(D34/(1-D34),0) -> 0.17647059 | F34: P&H | G34: Division names feed the SOV line names (Knowify uses 'HVAC'
B35: Ventilation | C35: V | D35: 0.15 | E35: =IFERROR(D35/(1-D35),0) -> 0.17647059 | F35: HVAC | G35: for ventilation; rename here if you prefer that).
B36: Air Conditioning | C36: AC | D36: 0.15 | E36: =IFERROR(D36/(1-D36),0) -> 0.17647059 | F36: HVAC
B38: LEVELS (SOV splits rough-in and finishing labour by level)
B39: Tag (e.g. BLDG A - L1) | C39: Floor | D39: Units | E39: SOV Weight %
B40: U/G | C40: Ground Work | E40: =IFERROR(D40/$D$64,0) -> 0 | G40: Units per level from original PRJ INFO C6:C10.
B41: P-02 | C41: Parking 2 | E41: =IFERROR(D41/$D$64,0) -> 0 | G41: Weight defaults to units share. Type over it to give parking,
B42: PRKG | C42: Parking 1 | E42: =IFERROR(D42/$D$64,0) -> 0 | G42: U/G or roof a share. Weights must total 100%.
B43: L-01 | C43: Level 1 | D43: 24 | E43: =IFERROR(D43/$D$64,0) -> 0.19512195 | G43: Multi-building jobs: use tags like 'BLDG A - L1' to match Knowify.
...

Sheet LABOUR RATES
A1: LABOUR RATES (crew mix)
A2: Same layout as the original PRJ INFO rates block. Both trades tie back the same way. | B2: UPDATED 2026-06-29
B4: PLUMBING & HYDRONIC CREW
B5: Classification | C5: Burdened Rate $/hr | D5: Crew Mix % | E5: Weighted $/hr | F5: Hours | G5: Cost by Wage Breakdown | H5: Knowify Actual $/hr | I5: Knowify Actual Mix
B6: Apprentice Lvl 1-2 | C6: 53 | D6: 0.4 | E6: =C6*D6 -> 21.2 | F6: =$C$15*D6 -> 590.4 | G6: =F6*C6 -> 31291.2 | H6: =IFERROR(INDEX('KNOWIFY REVIEW'!$E$66:$E$70,MATCH(B6,'KNOWIFY REVIEW'!$B$66:$B$70,0)),"") -> 40.248892 | I6: =IFERROR(INDEX('KNOWIFY REVIEW'!$F$66:$F$70,MATCH(B6,'KNOWIFY REVIEW'!$B$66:$B$70,0)),"") -> 0.36472509 | K6: Rates are fully burdened (confirmed): from original PRJ INFO D36:D40.
B7: Apprentice Lvl 3-6 | C7: 62.5 | D7: 0.3 | E7: =C7*D7 -> 18.75 | F7: =$C$15*D7 -> 442.8 | G7: =F7*C7 -> 27675 | H7: =IFERROR(INDEX('KNOWIFY REVIEW'!$E$66:$E$70,MATCH(B7,'KNOWIFY REVIEW'!$B$66:$B$70,0)),"") -> 47.102138 | I7: =IFERROR(INDEX('KNOWIFY REVIEW'!$F$66:$F$70,MATCH(B7,'KNOWIFY REVIEW'!$B$66:$B$70,0)),"") -> 0.24982948 | K7: Crew mix from original PRJ INFO E36:E40.
B8: Apprentice Lvl 7-8 | C8: 66.5 | D8: 0.05 | E8: =C8*D8 -> 3.325 | F8: =$C$15*D8 -> 73.8 | G8: =F8*C8 -> 4907.7 | H8: =IFERROR(INDEX('KNOWIFY REVIEW'!$E$66:$E$70,MATCH(B8,'KNOWIFY REVIEW'!$B$66:$B$70,0)),"") -> 51.21304 | I8: =IFERROR(INDEX('KNOWIFY REVIEW'!$F$66:$F$70,MATCH(B8,'KNOWIFY REVIEW'!$B$66:$B$70,0)),"") -> 0.085780851 | K8: Overhead $22/hr from original PRJ INFO H35/H44 (salaried staff, company wide).
B9: Journeyman Lvl 1-2 | C9: 73 | D9: 0.11 | E9: =C9*D9 -> 8.03 | F9: =$C$15*D9 -> 162.36 | G9: =F9*C9 -> 11852.28 | H9: =IFERROR(INDEX('KNOWIFY REVIEW'!$E$66:$E$70,MATCH(B9,'KNOWIFY REVIEW'!$B$66:$B$70,0)),"") -> 61.546529 | I9: =IFERROR(INDEX('KNOWIFY REVIEW'!$F$66:$F$70,MATCH(B9,'KNOWIFY REVIEW'!$B$66:$B$70,0)),"") -> 0.12010443 | K9: Knowify columns: company-wide actuals from KNOWIFY TIME (all trades together).
B10: Foreman & PM | C10: 96 | D10: 0.14 | E10: =C10*D10 -> 13.44 | F10: =$C$15*D10 -> 206.64 | G10: =F10*C10 -> 19837.44 | H10: =IFERROR(INDEX('KNOWIFY REVIEW'!$E$66:$E$70,MATCH(B10,'KNOWIFY REVIEW'!$B$66:$B$70,0)),"") -> 68.335403 | I10: =IFERROR(INDEX('KNOWIFY REVIEW'!$F$66:$F$70,MATCH(B10,'KNOWIFY REVIEW'!$B$66:$B$70,0)),"") -> 0.17956015 | K10: Knowify mix excludes 'Unmapped' roles, so it can total under 100%.
B11: Weighted average burdened wage | D11: =SUM(D6:D10) -> 1 | E11: =SUM(E6:E10) -> 64.745 | F11: =SUM(F6:F10) -> 1476 | G11: =SUM(G6:G10) -> 95563.62 | H11: ='KNOWIFY REVIEW'!$E$72 -> 50.502707 | I11: =SUM(I6:I10) -> 1
B12: Overhead $/hr (salaried staff, shop, office, insurance) | C12: 22
B13: FULLY LOADED RATE $/hr | C13: =E11+C12 -> 86.745
B14: Crew mix = 100% and hours x rate ties to breakdown | C14: =IF(AND(ABS(D11-1)<0.0001,ABS(G11-F11*E11)<1),"OK","CHECK") -> OK
B15: Estimated hours (from estimate tabs) | C15: =SUMIFS('PLUMBING EST'!$M$7:$M$156,'PLUMBING EST'!$B$7:$B$156,"P")+SUMIFS('HVAC EST'!$M$7:$M$156,'HVAC EST'!$B$7:$B$156,"P")+SUMIFS('PLUMBING EST'!$M$7:$M$156,'PLUMBING EST'!$B$7:$B$156,"H")+SUMIFS('HVAC EST'!$M$7:$M$156,'HVAC EST'!$B$7:$B$156,"H") -> 1476
B19: HVAC CREW (ventilation & A/C)
B20: Classification | C20: Burdened Rate $/hr | D20: Crew Mix % | E20: Weighted $/hr | F20: Hours | G20: Cost by Wage Breakdown | H20: Knowify Actual $/hr | I20: Knowify Actual Mix
B21: Apprentice Lvl 1-2 | C21: 53 | D21: 0.4 | E21: =C21*D21 -> 21.2 | F21: =$C$30*D21 -> 0 | G21: =F21*C21 -> 0 | H21: =IFERROR(INDEX('KNOWIFY REVIEW'!$E$66:$E$70,MATCH(B21,'KNOWIFY REVIEW'!$B$66:$B$70,0)),"") -> 40.248892 | I21: =IFERROR(INDEX('KNOWIFY REVIEW'!$F$66:$F$70,MATCH(B21,'KNOWIFY REVIEW'!$B$66:$B$70,0)),"") -> 0.36472509 | K21: Rates are fully burdened (confirmed): from original PRJ INFO D36:D40.
B22: Apprentice Lvl 3-6 | C22: 62.5 | D22: 0.3 | E22: =C22*D22 -> 18.75 | F22: =$C$30*D22 -> 0 | G22: =F22*C22 -> 0 | H22: =IFERROR(INDEX('KNOWIFY REVIEW'!$E$66:$E$70,MATCH(B22,'KNOWIFY REVIEW'!$B$66:$B$70,0)),"") -> 47.102138 | I22: =IFERROR(INDEX('KNOWIFY REVIEW'!$F$66:$F$70,MATCH(B22,'KNOWIFY REVIEW'!$B$66:$B$70,0)),"") -> 0.24982948 | K22: Crew mix from original PRJ INFO E36:E40.
B23: Apprentice Lvl 7-8 | C23: 66.5 | D23: 0.05 | E23: =C23*D23 -> 3.325 | F23: =$C$30*D23 -> 0 | G23: =F23*C23 -> 0 | H23: =IFERROR(INDEX('KNOWIFY REVIEW'!$E$66:$E$70,MATCH(B23,'KNOWIFY REVIEW'!$B$66:$B$70,0)),"") -> 51.21304 | I23: =IFERROR(INDEX('KNOWIFY REVIEW'!$F$66:$F$70,MATCH(B23,'KNOWIFY REVIEW'!$B$66:$B$70,0)),"") -> 0.085780851 | K23: Overhead $22/hr from original PRJ INFO H35/H44 (salaried staff, company wide).
B24: Journeyman Lvl 1-2 | C24: 73 | D24: 0.11 | E24: =C24*D24 -> 8.03 | F24: =$C$30*D24 -> 0 | G24: =F24*C24 -> 0 | H24: =IFERROR(INDEX('KNOWIFY REVIEW'!$E$66:$E$70,MATCH(B24,'KNOWIFY REVIEW'!$B$66:$B$70,0)),"") -> 61.546529 | I24: =IFERROR(INDEX('KNOWIFY REVIEW'!$F$66:$F$70,MATCH(B24,'KNOWIFY REVIEW'!$B$66:$B$70,0)),"") -> 0.12010443 | K24: Knowify columns: company-wide actuals from KNOWIFY TIME (all trades together).
B25: Foreman & PM | C25: 96 | D25: 0.14 | E25: =C25*D25 -> 13.44 | F25: =$C$30*D25 -> 0 | G25: =F25*C25 -> 0 | H25: =IFERROR(INDEX('KNOWIFY REVIEW'!$E$66:$E$70,MATCH(B25,'KNOWIFY REVIEW'!$B$66:$B$70,0)),"") -> 68.335403 | I25: =IFERROR(INDEX('KNOWIFY REVIEW'!$F$66:$F$70,MATCH(B25,'KNOWIFY REVIEW'!$B$66:$B$70,0)),"") -> 0.17956015 | K25: Knowify mix excludes 'Unmapped' roles, so it can total under 100%.
B26: Weighted average burdened wage | D26: =SUM(D21:D25) -> 1 | E26: =SUM(E21:E25) -> 64.745 | F26: =SUM(F21:F25) -> 0 | G26: =SUM(G21:G25) -> 0 | H26: ='KNOWIFY REVIEW'!$E$72 -> 50.502707 | I26: =SUM(I21:I25) -> 1
B27: Overhead $/hr (salaried staff, shop, office, insurance) | C27: 22
B28: FULLY LOADED RATE $/hr | C28: =E26+C27 -> 86.745
B29: Crew mix = 100% and hours x rate ties to breakdown | C29: =IF(AND(ABS(D26-1)<0.0001,ABS(G26-F26*E26)<1),"OK","CHECK") -> OK
B30: Estimated hours (from estimate tabs) | C30: =SUMIFS('PLUMBING EST'!$M$7:$M$156,'PLUMBING EST'!$B$7:$B$156,"V")+SUMIFS('HVAC EST'!$M$7:$M$156,'HVAC EST'!$B$7:$B$156,"V")+SUMIFS('PLUMBING EST'!$M$7:$M$156,'PLUMBING EST'!$B$7:$B$156,"AC")+SUMIFS('HVAC EST'!$M$7:$M$156,'HVAC EST'!$B$7:$B$156,"AC") -> 0
B33: RATE COMPARISON (per hour)
B34: Rate Basis | C34: $/hr | F34: P&H Est. Hours | G34: Labour (+OH) Cost
B35: Original template line items (Apprentice 1-2 only) | C35: =C6 -> 53 | F35: =$C$15 -> 1476 | G35: =C35*F35 -> 78228 | K35: If Knowify's cost per hour is well below the template rate, either Knowify
B36: Original template 'Budget with' (simple average) | C36: =AVERAGE(C6:C10) -> 70.2 | F36: =$C$15 -> 1476 | G36: =C36*F36 -> 103615.2 | K36: is missing burden, or the template rates are high. Settle which is true
B37: Crew-mix weighted burdened wage (this template) | C37: =E11 -> 64.745 | F37: =$C$15 -> 1476 | G37: =C37*F37 -> 95563.62 | K37: before trusting either for bids.
B38: Fully loaded: weighted wage + overhead | C38: =C13 -> 86.745 | F38: =$C$15 -> 1476 | G38: =C38*F38 -> 128035.62
B39: Knowify actual average cost per hour (job pasted) | C39: ='KNOWIFY REVIEW'!$E$72 -> 50.502707 | F39: =$C$15 -> 1476 | G39: =C39*F39 -> 74541.996
B40: Knowify actual + overhead | C40: ='KNOWIFY REVIEW'!$E$72+C12 -> 72.502707 | F40: =$C$15 -> 1476 | G40: =C40*F40 -> 107014

Sheet PLUMBING EST
A1: PLUMBING EST
A2: Plumbing (P) and Hydronic (H). Seed unit costs and hours from the original EQUIPMENT sheet.
A3: TOTALS | L3: =SUM(L7:L156) -> 105288 | M3: =SUM(M7:M156) -> 1476 | N3: =SUM(N7:N156) -> 95563.62 | O3: =SUM(O7:O156) -> 32472 | P3: =SUM(P7:P156) -> 233323.62
A4: Labour $ = Hours x crew-mix weighted burdened wage. Overhead $ = Hours x overhead $/hr. P/H rows use the P&H crew, V/AC rows use the HVAC crew. Q:R show how the same Div + Phase ran vs budget on the Knowify job pasted (1.30x = 30% over).
A6: Item Code | B6: Div | C6: Phase | D6: Description | E6: Qty | F6: Unit | G6: Material $/Unit | H6: Hrs/Unit | I6: Add Material $ | J6: Add Hrs | K6: PST? (Y/N) | L6: Material $ (incl PST) | M6: Hours | N6: Labour $ (wage+burden) | O6: Overhead $ | P6: TOTAL COST $ | Q6: Knowify Labour Actual/Budget | R6: Knowify Material Actual/Budget | S6: History Flag
A7: P-UG-SUMP | B7: P | C7: 02 Foundation & Underground | D7: Sumps & Interceptors | F7: ea | K7: Y | L7: =($E7*$G7+$I7)*(1+IF($K7="N",0,INPUTS!$C$23)) -> 0 | M7: =$E7*$H7+$J7 -> 0 | N7: =$M7*IF(OR($B7="V",$B7="AC"),'LABOUR RATES'!$E$26,'LABOUR RATES'!$E$11) -> 0 | O7: =$M7*IF(OR($B7="V",$B7="AC"),'LABOUR RATES'!$C$27,'LABOUR RATES'!$C$12) -> 0 | P7: =$L7+$N7+$O7 -> 0 | Q7: =IF(OR($B7="",$C7=""),"",IFERROR(SUMIFS('KNOWIFY REVIEW'!$AF$4:$AF$400,'KNOWIFY REVIEW'!$AB$4:$AB$400,$B7,'KNOWIFY REVIEW'!$AC$4:$AC$400,$C7,'KNOWIFY REVIEW'!$AD$4:$AD$400,1)/SUMIFS('KNOWIFY REVIEW'!$AE$4:$AE$400,'KNOWIFY REVIEW'!$AB$4:$AB$400,$B7,'KNOWIFY REVIEW'!$AC$4:$AC$400,$C7,'KNOWIFY REVIEW'!$AD$4:$AD$400,1),"")) -> 1.7292751 | R7: =IF(OR($B7="",$C7=""),"",IFERROR(SUMIFS('KNOWIFY REVIEW'!$AH$4:$AH$400,'KNOWIFY REVIEW'!$AB$4:$AB$400,$B7,'KNOWIFY REVIEW'!$AC$4:$AC$400,IF(OR($C7=INPUTS!$B$69,$C7=INPUTS!$B$70),INPUTS!$B$71,$C7),'KNOWIFY REVIEW'!$AD$4:$AD$400,1)/SUMIFS('KNOWIFY REVIEW'!$AG$4:$AG$400,'KNOWIFY REVIEW'!$AB$4:$AB$400,$B7,'KNOWIFY REVIEW'!$AC$4:$AC$400,IF(OR($C7=INPUTS!$B$69,$C7=INPUTS!$B$70),INPUTS!$B$71,$C7),'KNOWIFY REVIEW'!$AD$4:$AD$400,1),"")) -> 1.022045 | S7: =IF(MAX(N($Q7),N($R7))>1.1,"Past job ran over budget","") -> Past job ran over budget
A8: P-UG-STRM | B8: P | C8: 02 Foundation & Underground | D8: Storm Water & Drain Tile | F8: lf | K8: Y | L8: =($E8*$G8+$I8)*(1+IF($K8="N",0,INPUTS!$C$23)) -> 0 | M8: =$E8*$H8+$J8 -> 0 | N8: =$M8*IF(OR($B8="V",$B8="AC"),'LABOUR RATES'!$E$26,'LABOUR RATES'!$E$11) -> 0 | O8: =$M8*IF(OR($B8="V",$B8="AC"),'LABOUR RATES'!$C$27,'LABOUR RATES'!$C$12) -> 0 | P8: =$L8+$N8+$O8 -> 0 | Q8: =IF(OR($B8="",$C8=""),"",IFERROR(SUMIFS('KNOWIFY REVIEW'!$AF$4:$AF$400,'KNOWIFY REVIEW'!$AB$4:$AB$400,$B8,'KNOWIFY REVIEW'!$AC$4:$AC$400,$C8,'KNOWIFY REVIEW'!$AD$4:$AD$400,1)/SUMIFS('KNOWIFY REVIEW'!$AE$4:$AE$400,'KNOWIFY REVIEW'!$AB$4:$AB$400,$B8,'KNOWIFY REVIEW'!$AC$4:$AC$400,$C8,'KNOWIFY REVIEW'!$AD$4:$AD$400,1),"")) -> 1.7292751 | R8: =IF(OR($B8="",$C8=""),"",IFERROR(SUMIFS('KNOWIFY REVIEW'!$AH$4:$AH$400,'KNOWIFY REVIEW'!$AB$4:$AB$400,$B8,'KNOWIFY REVIEW'!$AC$4:$AC$400,IF(OR($C8=INPUTS!$B$69,$C8=INPUTS!$B$70),INPUTS!$B$71,$C8),'KNOWIFY REVIEW'!$AD$4:$AD$400,1)/SUMIFS('KNOWIFY REVIEW'!$AG$4:$AG$400,'KNOWIFY REVIEW'!$AB$4:$AB$400,$B8,'KNOWIFY REVIEW'!$AC$4:$AC$400,IF(OR($C8=INPUTS!$B$69,$C8=INPUTS!$B$70),INPUTS!$B$71,$C8),'KNOWIFY REVIEW'!$AD$4:$AD$400,1),"")) -> 1.022045 | S8: =IF(MAX(N($Q8),N($R8))>1.1,"Past job ran over budget","") -> Past job ran over budget
A9: P-UG-SAN | B9: P | C9: 02 Foundation & Underground | D9: Sanitary (underground) | F9: lf | K9: Y | L9: =($E9*$G9+$I9)*(1+IF($K9="N",0,INPUTS!$C$23)) -> 0 | M9: =$E9*$H9+$J9 -> 0 | N9: =$M9*IF(OR($B9="V",$B9="AC"),'LABOUR RATES'!$E$26,'LABOUR RATES'!$E$11) -> 0 | O9: =$M9*IF(OR($B9="V",$B9="AC"),'LABOUR RATES'!$C$27,'LABOUR RATES'!$C$12) -> 0 | P9: =$L9+$N9+$O9 -> 0 | Q9: =IF(OR($B9="",$C9=""),"",IFERROR(SUMIFS('KNOWIFY REVIEW'!$AF$4:$AF$400,'KNOWIFY REVIEW'!$AB$4:$AB$400,$B9,'KNOWIFY REVIEW'!$AC$4:$AC$400,$C9,'KNOWIFY REVIEW'!$AD$4:$AD$400,1)/SUMIFS('KNOWIFY REVIEW'!$AE$4:$AE$400,'KNOWIFY REVIEW'!$AB$4:$AB$400,$B9,'KNOWIFY REVIEW'!$AC$4:$AC$400,$C9,'KNOWIFY REVIEW'!$AD$4:$AD$400,1),"")) -> 1.7292751 | R9: =IF(OR($B9="",$C9=""),"",IFERROR(SUMIFS('KNOWIFY REVIEW'!$AH$4:$AH$400,'KNOWIFY REVIEW'!$AB$4:$AB$400,$B9,'KNOWIFY REVIEW'!$AC$4:$AC$400,IF(OR($C9=INPUTS!$B$69,$C9=INPUTS!$B$70),INPUTS!$B$71,$C9),'KNOWIFY REVIEW'!$AD$4:$AD$400,1)/SUMIFS('KNOWIFY REVIEW'!$AG$4:$AG$400,'KNOWIFY REVIEW'!$AB$4:$AB$400,$B9,'KNOWIFY REVIEW'!$AC$4:$AC$400,IF(OR($C9=INPUTS!$B$69,$C9=INPUTS!$B$70),INPUTS!$B$71,$C9),'KNOWIFY REVIEW'!$AD$4:$AD$400,1),"")) -> 1.022045 | S9: =IF(MAX(N($Q9),N($R9))>1.1,"Past job ran over budget","") -> Past job ran over budget
A10: P-UG-DW | B10: P | C10: 02 Foundation & Underground | D10: Domestic Water (underground) | F10: lf | K10: Y | L10: =($E10*$G10+$I10)*(1+IF($K10="N",0,INPUTS!$C$23)) -> 0 | M10: =$E10*$H10+$J10 -> 0 | N10: =$M10*IF(OR($B10="V",$B10="AC"),'LABOUR RATES'!$E$26,'LABOUR RATES'!$E$11) -> 0 | O10: =$M10*IF(OR($B10="V",$B10="AC"),'LABOUR RATES'!$C$27,'LABOUR RATES'!$C$12) -> 0 | P10: =$L10+$N10+$O10 -> 0 | Q10: =IF(OR($B10="",$C10=""),"",IFERROR(SUMIFS('KNOWIFY REVIEW'!$AF$4:$AF$400,'KNOWIFY REVIEW'!$AB$4:$AB$400,$B10,'KNOWIFY REVIEW'!$AC$4:$AC$400,$C10,'KNOWIFY REVIEW'!$AD$4:$AD$400,1)/SUMIFS('KNOWIFY REVIEW'!$AE$4:$AE$400,'KNOWIFY REVIEW'!$AB$4:$AB$400,$B10,'KNOWIFY REVIEW'!$AC$4:$AC$400,$C10,'KNOWIFY REVIEW'!$AD$4:$AD$400,1),"")) -> 1.7292751 | R10: =IF(OR($B10="",$C10=""),"",IFERROR(SUMIFS('KNOWIFY REVIEW'!$AH$4:$AH$400,'KNOWIFY REVIEW'!$AB$4:$AB$400,$B10,'KNOWIFY REVIEW'!$AC$4:$AC$400,IF(OR($C10=INPUTS!$B$69,$C10=INPUTS!$B$70),INPUTS!$B$71,$C10),'KNOWIFY REVIEW'!$AD$4:$AD$400,1)/SUMIFS('KNOWIFY REVIEW'!$AG$4:$AG$400,'KNOWIFY REVIEW'!$AB$4:$AB$400,$B10,'KNOWIFY REVIEW'!$AC$4:$AC$400,IF(OR($C10=INPUTS!$B$69,$C10=INPUTS!$B$70),INPUTS!$B$71,$C10),'KNOWIFY REVIEW'!$AD$4:$AD$400,1),"")) -> 1.022045 | S10: =IF(MAX(N($Q10),N($R10))>1.1,"Past job ran over budget","") -> Past job ran over budget
A11: P-RI-STRM | B11: P | C11: 03 Rough-in (Labour) | D11: DWV Storm Water | F11: lf | K11: Y | L11: =($E11*$G11+$I11)*(1+IF($K11="N",0,INPUTS!$C$23)) -> 0 | M11: =$E11*$H11+$J11 -> 0 | N11: =$M11*IF(OR($B11="V",$B11="AC"),'LABOUR RATES'!$E$26,'LABOUR RATES'!$E$11) -> 0 | O11: =$M11*IF(OR($B11="V",$B11="AC"),'LABOUR RATES'!$C$27,'LABOUR RATES'!$C$12) -> 0 | P11: =$L11+$N11+$O11 -> 0 | Q11: =IF(OR($B11="",$C11=""),"",IFERROR(SUMIFS('KNOWIFY REVIEW'!$AF$4:$AF$400,'KNOWIFY REVIEW'!$AB$4:$AB$400,$B11,'KNOWIFY REVIEW'!$AC$4:$AC$400,$C11,'KNOWIFY REVIEW'!$AD$4:$AD$400,1)/SUMIFS('KNOWIFY REVIEW'!$AE$4:$AE$400,'KNOWIFY REVIEW'!$AB$4:$AB$400,$B11,'KNOWIFY REVIEW'!$AC$4:$AC$400,$C11,'KNOWIFY REVIEW'!$AD$4:$AD$400,1),"")) -> 1.3492499 | R11: =IF(OR($B11="",$C11=""),"",IFERROR(SUMIFS('KNOWIFY REVIEW'!$AH$4:$AH$400,'KNOWIFY REVIEW'!$AB$4:$AB$400,$B11,'KNOWIFY REVIEW'!$AC$4:$AC$400,IF(OR($C11=INPUTS!$B$69,$C11=INPUTS!$B$70),INPUTS!$B$71,$C11),'KNOWIFY REVIEW'!$AD$4:$AD$400,1)/SUMIFS('KNOWIFY REVIEW'!$AG$4:$AG$400,'KNOWIFY REVIEW'!$AB$4:$AB$400,$B11,'KNOWIFY REVIEW'!$AC$4:$AC$400,IF(OR($C11=INPUTS!$B$69,$C11=INPUTS!$B$70),INPUTS!$B$71,$C11),'KNOWIFY REVIEW'!$AD$4:$AD$400,1),"")) -> 1.2924123 | S11: =IF(MAX(N($Q11),N($R11))>1.1,"Past job ran over budget","") -> Past job ran over budget
A12: P-RI-SAN | B12: P | C12: 03 Rough-in (Labour) | D12: DWV Sanitary (Drainage/Vents) | F12: lf | K12: Y | L12: =($E12*$G12+$I12)*(1+IF($K12="N",0,INPUTS!$C$23)) -> 0 | M12: =$E12*$H12+$J12 -> 0 | N12: =$M12*IF(OR($B12="V",$B12="AC"),'LABOUR RATES'!$E$26,'LABOUR RATES'!$E$11) -> 0 | O12: =$M12*IF(OR($B12="V",$B12="AC"),'LABOUR RATES'!$C$27,'LABOUR RATES'!$C$12) -> 0 | P12: =$L12+$N12+$O12 -> 0 | Q12: =IF(OR($B12="",$C12=""),"",IFERROR(SUMIFS('KNOWIFY REVIEW'!$AF$4:$AF$400,'KNOWIFY REVIEW'!$AB$4:$AB$400,$B12,'KNOWIFY REVIEW'!$AC$4:$AC$400,$C12,'KNOWIFY REVIEW'!$AD$4:$AD$400,1)/SUMIFS('KNOWIFY REVIEW'!$AE$4:$AE$400,'KNOWIFY REVIEW'!$AB$4:$AB$400,$B12,'KNOWIFY REVIEW'!$AC$4:$AC$400,$C12,'KNOWIFY REVIEW'!$AD$4:$AD$400,1),"")) -> 1.3492499 | R12: =IF(OR($B12="",$C12=""),"",IFERROR(SUMIFS('KNOWIFY REVIEW'!$AH$4:$AH$400,'KNOWIFY REVIEW'!$AB$4:$AB$400,$B12,'KNOWIFY REVIEW'!$AC$4:$AC$400,IF(OR($C12=INPUTS!$B$69,$C12=INPUTS!$B$70),INPUTS!$B$71,$C12),'KNOWIFY REVIEW'!$AD$4:$AD$400,1)/SUMIFS('KNOWIFY REVIEW'!$AG$4:$AG$400,'KNOWIFY REVIEW'!$AB$4:$AB$400,$B12,'KNOWIFY REVIEW'!$AC$4:$AC$400,IF(OR($C12=INPUTS!$B$69,$C12=INPUTS!$B$70),INPUTS!$B$71,$C12),'KNOWIFY REVIEW'!$AD$4:$AD$400,1),"")) -> 1.2924123 | S12: =IF(MAX(N($Q12),N($R12))>1.1,"Past job ran over budget","") -> Past job ran over budget
A13: P-RI-WR2 | B13: P | C13: 03 Rough-in (Labour) | D13: 2-Piece Bathroom (WC, LAV) | F13: ea | G13: 550 | H13: 3 | K13: Y | L13: =($E13*$G13+$I13)*(1+IF($K13="N",0,INPUTS!$C$23)) -> 0 | M13: =$E13*$H13+$J13 -> 0 | N13: =$M13*IF(OR($B13="V",$B13="AC"),'LABOUR RATES'!$E$26,'LABOUR RATES'!$E$11) -> 0 | O13: =$M13*IF(OR($B13="V",$B13="AC"),'LABOUR RATES'!$C$27,'LABOUR RATES'!$C$12) -> 0 | P13: =$L13+$N13+$O13 -> 0 | Q13: =IF(OR($B13="",$C13=""),"",IFERROR(SUMIFS('KNOWIFY REVIEW'!$AF$4:$AF$400,'KNOWIFY REVIEW'!$AB$4:$AB$400,$B13,'KNOWIFY REVIEW'!$AC$4:$AC$400,$C13,'KNOWIFY REVIEW'!$AD$4:$AD$400,1)/SUMIFS('KNOWIFY REVIEW'!$AE$4:$AE$400,'KNOWIFY REVIEW'!$AB$4:$AB$400,$B13,'KNOWIFY REVIEW'!$AC$4:$AC$400,$C13,'KNOWIFY REVIEW'!$AD$4:$AD$400,1),"")) -> 1.3492499 | R13: =IF(OR($B13="",$C13=""),"",IFERROR(SUMIFS('KNOWIFY REVIEW'!$AH$4:$AH$400,'KNOWIFY REVIEW'!$AB$4:$AB$400,$B13,'KNOWIFY REVIEW'!$AC$4:$AC$400,IF(OR($C13=INPUTS!$B$69,$C13=INPUTS!$B$70),INPUTS!$B$71,$C13),'KNOWIFY REVIEW'!$AD$4:$AD$400,1)/SUMIFS('KNOWIFY REVIEW'!$AG$4:$AG$400,'KNOWIFY REVIEW'!$AB$4:$AB$400,$B13,'KNOWIFY REVIEW'!$AC$4:$AC$400,IF(OR($C13=INPUTS!$B$69,$C13=INPUTS!$B$70),INPUTS!$B$71,$C13),'KNOWIFY REVIEW'!$AD$4:$AD$400,1),"")) -> 1.2924123 | S13: =IF(MAX(N($Q13),N($R13))>1.1,"Past job ran over budget","") -> Past job ran over budget
A14: P-RI-WR3T | B14: P | C14: 03 Rough-in (Labour) | D14: 3-Piece Bathroom (WC, LAV, TUB) | F14: ea | G14: 860 | H14: 5 | K14: Y | L14: =($E14*$G14+$I14)*(1+IF($K14="N",0,INPUTS!$C$23)) -> 0 | M14: =$E14*$H14+$J14 -> 0 | N14: =$M14*IF(OR($B14="V",$B14="AC"),'LABOUR RATES'!$E$26,'LABOUR RATES'!$E$11) -> 0 | O14: =$M14*IF(OR($B14="V",$B14="AC"),'LABOUR RATES'!$C$27,'LABOUR RATES'!$C$12) -> 0 | P14: =$L14+$N14+$O14 -> 0 | Q14: =IF(OR($B14="",$C14=""),"",IFERROR(SUMIFS('KNOWIFY REVIEW'!$AF$4:$AF$400,'KNOWIFY REVIEW'!$AB$4:$AB$400,$B14,'KNOWIFY REVIEW'!$AC$4:$AC$400,$C14,'KNOWIFY REVIEW'!$AD$4:$AD$400,1)/SUMIFS('KNOWIFY REVIEW'!$AE$4:$AE$400,'KNOWIFY REVIEW'!$AB$4:$AB$400,$B14,'KNOWIFY REVIEW'!$AC$4:$AC$400,$C14,'KNOWIFY REVIEW'!$AD$4:$AD$400,1),"")) -> 1.3492499 | R14: =IF(OR($B14="",$C14=""),"",IFERROR(SUMIFS('KNOWIFY REVIEW'!$AH$4:$AH$400,'KNOWIFY REVIEW'!$AB$4:$AB$400,$B14,'KNOWIFY REVIEW'!$AC$4:$AC$400,IF(OR($C14=INPUTS!$B$69,$C14=INPUTS!$B$70),INPUTS!$B$71,$C14),'KNOWIFY REVIEW'!$AD$4:$AD$400,1)/SUMIFS('KNOWIFY REVIEW'!$AG$4:$AG$400,'KNOWIFY REVIEW'!$AB$4:$AB$400,$B14,'KNOWIFY REVIEW'!$AC$4:$AC$400,IF(OR($C14=INPUTS!$B$69,$C14=INPUTS!$B$70),INPUTS!$B$71,$C14),'KNOWIFY REVIEW'!$AD$4:$AD$400,1),"")) -> 1.2924123 | S14: =IF(MAX(N($Q14),N($R14))>1.1,"Past job ran over budget","") -> Past job ran over budget
A15: P-RI-WR3S | B15: P | C15: 03 Rough-in (Labour) | D15: 3-Piece Bathroom (WC, LAV, SH) | F15: ea | G15: 860 | H15: 5 | K15: Y | L15: =($E15*$G15+$I15)*(1+IF($K15="N",0,INPUTS!$C$23)) -> 0 | M15: =$E15*$H15+$J15 -> 0 | N15: =$M15*IF(OR($B15="V",$B15="AC"),'LABOUR RATES'!$E$26,'LABOUR RATES'!$E$11) -> 0 | O15: =$M15*IF(OR($B15="V",$B15="AC"),'LABOUR RATES'!$C$27,'LABOUR RATES'!$C$12) -> 0 | P15: =$L15+$N15+$O15 -> 0 | Q15: =IF(OR($B15="",$C15=""),"",IFERROR(SUMIFS('KNOWIFY REVIEW'!$AF$4:$AF$400,'KNOWIFY REVIEW'!$AB$4:$AB$400,$B15,'KNOWIFY REVIEW'!$AC$4:$AC$400,$C15,'KNOWIFY REVIEW'!$AD$4:$AD$400,1)/SUMIFS('KNOWIFY REVIEW'!$AE$4:$AE$400,'KNOWIFY REVIEW'!$AB$4:$AB$400,$B15,'KNOWIFY REVIEW'!$AC$4:$AC$400,$C15,'KNOWIFY REVIEW'!$AD$4:$AD$400,1),"")) -> 1.3492499 | R15: =IF(OR($B15="",$C15=""),"",IFERROR(SUMIFS('KNOWIFY REVIEW'!$AH$4:$AH$400,'KNOWIFY REVIEW'!$AB$4:$AB$400,$B15,'KNOWIFY REVIEW'!$AC$4:$AC$400,IF(OR($C15=INPUTS!$B$69,$C15=INPUTS!$B$70),INPUTS!$B$71,$C15),'KNOWIFY REVIEW'!$AD$4:$AD$400,1)/SUMIFS('KNOWIFY REVIEW'!$AG$4:$AG$400,'KNOWIFY REVIEW'!$AB$4:$AB$400,$B15,'KNOWIFY REVIEW'!$AC$4:$AC$400,IF(OR($C15=INPUTS!$B$69,$C15=INPUTS!$B$70),INPUTS!$B$71,$C15),'KNOWIFY REVIEW'!$AD$4:$AD$400,1),"")) -> 1.2924123 | S15: =IF(MAX(N($Q15),N($R15))>1.1,"Past job ran over budget","") -> Past job ran over budget
A16: P-RI-WR4T | B16: P | C16: 03 Rough-in (Labour) | D16: 4-Piece Bathroom (WC, 2LAV, TUB) | F16: ea | G16: 990 | H16: 6 | K16: Y | L16: =($E16*$G16+$I16)*(1+IF($K16="N",0,INPUTS!$C$23)) -> 0 | M16: =$E16*$H16+$J16 -> 0 | N16: =$M16*IF(OR($B16="V",$B16="AC"),'LABOUR RATES'!$E$26,'LABOUR RATES'!$E$11) -> 0 | O16: =$M16*IF(OR($B16="V",$B16="AC"),'LABOUR RATES'!$C$27,'LABOUR RATES'!$C$12) -> 0 | P16: =$L16+$N16+$O16 -> 0 | Q16: =IF(OR($B16="",$C16=""),"",IFERROR(SUMIFS('KNOWIFY REVIEW'!$AF$4:$AF$400,'KNOWIFY REVIEW'!$AB$4:$AB$400,$B16,'KNOWIFY REVIEW'!$AC$4:$AC$400,$C16,'KNOWIFY REVIEW'!$AD$4:$AD$400,1)/SUMIFS('KNOWIFY REVIEW'!$AE$4:$AE$400,'KNOWIFY REVIEW'!$AB$4:$AB$400,$B16,'KNOWIFY REVIEW'!$AC$4:$AC$400,$C16,'KNOWIFY REVIEW'!$AD$4:$AD$400,1),"")) -> 1.3492499 | R16: =IF(OR($B16="",$C16=""),"",IFERROR(SUMIFS('KNOWIFY REVIEW'!$AH$4:$AH$400,'KNOWIFY REVIEW'!$AB$4:$AB$400,$B16,'KNOWIFY REVIEW'!$AC$4:$AC$400,IF(OR($C16=INPUTS!$B$69,$C16=INPUTS!$B$70),INPUTS!$B$71,$C16),'KNOWIFY REVIEW'!$AD$4:$AD$400,1)/SUMIFS('KNOWIFY REVIEW'!$AG$4:$AG$400,'KNOWIFY REVIEW'!$AB$4:$AB$400,$B16,'KNOWIFY REVIEW'!$AC$4:$AC$400,IF(OR($C16=INPUTS!$B$69,$C16=INPUTS!$B$70),INPUTS!$B$71,$C16),'KNOWIFY REVIEW'!$AD$4:$AD$400,1),"")) -> 1.2924123 | S16: =IF(MAX(N($Q16),N($R16))>1.1,"Past job ran over budget","") -> Past job ran over budget
A17: P-RI-WR4S | B17: P | C17: 03 Rough-in (Labour) | D17: 4-Piece Bathroom (WC, 2LAV, SH) | F17: ea | G17: 990 | H17: 6 | K17: Y | L17: =($E17*$G17+$I17)*(1+IF($K17="N",0,INPUTS!$C$23)) -> 0 | M17: =$E17*$H17+$J17 -> 0 | N17: =$M17*IF(OR($B17="V",$B17="AC"),'LABOUR RATES'!$E$26,'LABOUR RATES'!$E$11) -> 0 | O17: =$M17*IF(OR($B17="V",$B17="AC"),'LABOUR RATES'!$C$27,'LABOUR RATES'!$C$12) -> 0 | P17: =$L17+$N17+$O17 -> 0 | Q17: =IF(OR($B17="",$C17=""),"",IFERROR(SUMIFS('KNOWIFY REVIEW'!$AF$4:$AF$400,'KNOWIFY REVIEW'!$AB$4:$AB$400,$B17,'KNOWIFY REVIEW'!$AC$4:$AC$400,$C17,'KNOWIFY REVIEW'!$AD$4:$AD$400,1)/SUMIFS('KNOWIFY REVIEW'!$AE$4:$AE$400,'KNOWIFY REVIEW'!$AB$4:$AB$400,$B17,'KNOWIFY REVIEW'!$AC$4:$AC$400,$C17,'KNOWIFY REVIEW'!$AD$4:$AD$400,1),"")) -> 1.3492499 | R17: =IF(OR($B17="",$C17=""),"",IFERROR(SUMIFS('KNOWIFY REVIEW'!$AH$4:$AH$400,'KNOWIFY REVIEW'!$AB$4:$AB$400,$B17,'KNOWIFY REVIEW'!$AC$4:$AC$400,IF(OR($C17=INPUTS!$B$69,$C17=INPUTS!$B$70),INPUTS!$B$71,$C17),'KNOWIFY REVIEW'!$AD$4:$AD$400,1)/SUMIFS('KNOWIFY REVIEW'!$AG$4:$AG$400,'KNOWIFY REVIEW'!$AB$4:$AB$400,$B17,'KNOWIFY REVIEW'!$AC$4:$AC$400,IF(OR($C17=INPUTS!$B$69,$C17=INPUTS!$B$70),INPUTS!$B$71,$C17),'KNOWIFY REVIEW'!$AD$4:$AD$400,1),"")) -> 1.2924123 | S17: =IF(MAX(N($Q17),N($R17))>1.1,"Past job ran over budget","") -> Past job ran over budget
A18: P-RI-WR4TS | B18: P | C18: 03 Rough-in (Labour) | D18: 4-Piece Bathroom (WC, LAV, TUB & SH) | F18: ea | G18: 1310 | H18: 6 | K18: Y | L18: =($E18*$G18+$I18)*(1+IF($K18="N",0,INPUTS!$C$23)) -> 0 | M18: =$E18*$H18+$J18 -> 0 | N18: =$M18*IF(OR($B18="V",$B18="AC"),'LABOUR RATES'!$E$26,'LABOUR RATES'!$E$11) -> 0 | O18: =$M18*IF(OR($B18="V",$B18="AC"),'LABOUR RATES'!$C$27,'LABOUR RATES'!$C$12) -> 0 | P18: =$L18+$N18+$O18 -> 0 | Q18: =IF(OR($B18="",$C18=""),"",IFERROR(SUMIFS('KNOWIFY REVIEW'!$AF$4:$AF$400,'KNOWIFY REVIEW'!$AB$4:$AB$400,$B18,'KNOWIFY REVIEW'!$AC$4:$AC$400,$C18,'KNOWIFY REVIEW'!$AD$4:$AD$400,1)/SUMIFS('KNOWIFY REVIEW'!$AE$4:$AE$400,'KNOWIFY REVIEW'!$AB$4:$AB$400,$B18,'KNOWIFY REVIEW'!$AC$4:$AC$400,$C18,'KNOWIFY REVIEW'!$AD$4:$AD$400,1),"")) -> 1.3492499 | R18: =IF(OR($B18="",$C18=""),"",IFERROR(SUMIFS('KNOWIFY REVIEW'!$AH$4:$AH$400,'KNOWIFY REVIEW'!$AB$4:$AB$400,$B18,'KNOWIFY REVIEW'!$AC$4:$AC$400,IF(OR($C18=INPUTS!$B$69,$C18=INPUTS!$B$70),INPUTS!$B$71,$C18),'KNOWIFY REVIEW'!$AD$4:$AD$400,1)/SUMIFS('KNOWIFY REVIEW'!$AG$4:$AG$400,'KNOWIFY REVIEW'!$AB$4:$AB$400,$B18,'KNOWIFY REVIEW'!$AC$4:$AC$400,IF(OR($C18=INPUTS!$B$69,$C18=INPUTS!$B$70),INPUTS!$B$71,$C18),'KNOWIFY REVIEW'!$AD$4:$AD$400,1),"")) -> 1.2924123 | S18: =IF(MAX(N($Q18),N($R18))>1.1,"Past job ran over budget","") -> Past job ran over budget
A19: P-RI-WR5 | B19: P | C19: 03 Rough-in (Labour) | D19: 5-Piece Bathroom (WC, 2LAV, TUB & SH) | F19: ea | G19: 1460 | H19: 6 | K19: Y | L19: =($E19*$G19+$I19)*(1+IF($K19="N",0,INPUTS!$C$23)) -> 0 | M19: =$E19*$H19+$J19 -> 0 | N19: =$M19*IF(OR($B19="V",$B19="AC"),'LABOUR RATES'!$E$26,'LABOUR RATES'!$E$11) -> 0 | O19: =$M19*IF(OR($B19="V",$B19="AC"),'LABOUR RATES'!$C$27,'LABOUR RATES'!$C$12) -> 0 | P19: =$L19+$N19+$O19 -> 0 | Q19: =IF(OR($B19="",$C19=""),"",IFERROR(SUMIFS('KNOWIFY REVIEW'!$AF$4:$AF$400,'KNOWIFY REVIEW'!$AB$4:$AB$400,$B19,'KNOWIFY REVIEW'!$AC$4:$AC$400,$C19,'KNOWIFY REVIEW'!$AD$4:$AD$400,1)/SUMIFS('KNOWIFY REVIEW'!$AE$4:$AE$400,'KNOWIFY REVIEW'!$AB$4:$AB$400,$B19,'KNOWIFY REVIEW'!$AC$4:$AC$400,$C19,'KNOWIFY REVIEW'!$AD$4:$AD$400,1),"")) -> 1.3492499 | R19: =IF(OR($B19="",$C19=""),"",IFERROR(SUMIFS('KNOWIFY REVIEW'!$AH$4:$AH$400,'KNOWIFY REVIEW'!$AB$4:$AB$400,$B19,'KNOWIFY REVIEW'!$AC$4:$AC$400,IF(OR($C19=INPUTS!$B$69,$C19=INPUTS!$B$70),INPUTS!$B$71,$C19),'KNOWIFY REVIEW'!$AD$4:$AD$400,1)/SUMIFS('KNOWIFY REVIEW'!$AG$4:$AG$400,'KNOWIFY REVIEW'!$AB$4:$AB$400,$B19,'KNOWIFY REVIEW'!$AC$4:$AC$400,IF(OR($C19=INPUTS!$B$69,$C19=INPUTS!$B$70),INPUTS!$B$71,$C19),'KNOWIFY REVIEW'!$AD$4:$AD$400,1),"")) -> 1.2924123 | S19: =IF(MAX(N($Q19),N($R19))>1.1,"Past job ran over budget","") -> Past job ran over budget
A20: P-RI-LAUN | B20: P | C20: 03 Rough-in (Labour) | D20: Laundry - 4" Wet Vent | F20: ea | G20: 280 | H20: 2 | K20: Y | L20: =($E20*$G20+$I20)*(1+IF($K20="N",0,INPUTS!$C$23)) -> 0 | M20: =$E20*$H20+$J20 -> 0 | N20: =$M20*IF(OR($B20="V",$B20="AC"),'LABOUR RATES'!$E$26,'LABOUR RATES'!$E$11) -> 0 | O20: =$M20*IF(OR($B20="V",$B20="AC"),'LABOUR RATES'!$C$27,'LABOUR RATES'!$C$12) -> 0 | P20: =$L20+$N20+$O20 -> 0 | Q20: =IF(OR($B20="",$C20=""),"",IFERROR(SUMIFS('KNOWIFY REVIEW'!$AF$4:$AF$400,'KNOWIFY REVIEW'!$AB$4:$AB$400,$B20,'KNOWIFY REVIEW'!$AC$4:$AC$400,$C20,'KNOWIFY REVIEW'!$AD$4:$AD$400,1)/SUMIFS('KNOWIFY REVIEW'!$AE$4:$AE$400,'KNOWIFY REVIEW'!$AB$4:$AB$400,$B20,'KNOWIFY REVIEW'!$AC$4:$AC$400,$C20,'KNOWIFY REVIEW'!$AD$4:$AD$400,1),"")) -> 1.3492499 | R20: =IF(OR($B20="",$C20=""),"",IFERROR(SUMIFS('KNOWIFY REVIEW'!$AH$4:$AH$400,'KNOWIFY REVIEW'!$AB$4:$AB$400,$B20,'KNOWIFY REVIEW'!$AC$4:$AC$400,IF(OR($C20=INPUTS!$B$69,$C20=INPUTS!$B$70),INPUTS!$B$71,$C20),'KNOWIFY REVIEW'!$AD$4:$AD$400,1)/SUMIFS('KNOWIFY REVIEW'!$AG$4:$AG$400,'KNOWIFY REVIEW'!$AB$4:$AB$400,$B20,'KNOWIFY REVIEW'!$AC$4:$AC$400,IF(OR($C20=INPUTS!$B$69,$C20=INPUTS!$B$70),INPUTS!$B$71,$C20),'KNOWIFY REVIEW'!$AD$4:$AD$400,1),"")) -> 1.2924123 | S20: =IF(MAX(N($Q20),N($R20))>1.1,"Past job ran over budget","") -> Past job ran over budget
A21: P-RI-KS3 | B21: P | C21: 03 Rough-in (Labour) | D21: Kitchen Sink - 3" Vent | F21: ea | G21: 240 | H21: 2 | K21: Y | L21: =($E21*$G21+$I21)*(1+IF($K21="N",0,INPUTS!$C$23)) -> 0 | M21: =$E21*$H21+$J21 -> 0 | N21: =$M21*IF(OR($B21="V",$B21="AC"),'LABOUR RATES'!$E$26,'LABOUR RATES'!$E$11) -> 0 | O21: =$M21*IF(OR($B21="V",$B21="AC"),'LABOUR RATES'!$C$27,'LABOUR RATES'!$C$12) -> 0 | P21: =$L21+$N21+$O21 -> 0 | Q21: =IF(OR($B21="",$C21=""),"",IFERROR(SUMIFS('KNOWIFY REVIEW'!$AF$4:$AF$400,'KNOWIFY REVIEW'!$AB$4:$AB$400,$B21,'KNOWIFY REVIEW'!$AC$4:$AC$400,$C21,'KNOWIFY REVIEW'!$AD$4:$AD$400,1)/SUMIFS('KNOWIFY REVIEW'!$AE$4:$AE$400,'KNOWIFY REVIEW'!$AB$4:$AB$400,$B21,'KNOWIFY REVIEW'!$AC$4:$AC$400,$C21,'KNOWIFY REVIEW'!$AD$4:$AD$400,1),"")) -> 1.3492499 | R21: =IF(OR($B21="",$C21=""),"",IFERROR(SUMIFS('KNOWIFY REVIEW'!$AH$4:$AH$400,'KNOWIFY REVIEW'!$AB$4:$AB$400,$B21,'KNOWIFY REVIEW'!$AC$4:$AC$400,IF(OR($C21=INPUTS!$B$69,$C21=INPUTS!$B$70),INPUTS!$B$71,$C21),'KNOWIFY REVIEW'!$AD$4:$AD$400,1)/SUMIFS('KNOWIFY REVIEW'!$AG$4:$AG$400,'KNOWIFY REVIEW'!$AB$4:$AB$400,$B21,'KNOWIFY REVIEW'!$AC$4:$AC$400,IF(OR($C21=INPUTS!$B$69,$C21=INPUTS!$B$70),INPUTS!$B$71,$C21),'KNOWIFY REVIEW'!$AD$4:$AD$400,1),"")) -> 1.2924123 | S21: =IF(MAX(N($Q21),N($R21))>1.1,"Past job ran over budget","") -> Past job ran over budget
A22: P-RI-KS4 | B22: P | C22: 03 Rough-in (Labour) | D22: Kitchen Sink - 4" Vent | F22: ea | G22: 250 | H22: 2 | K22: Y | L22: =($E22*$G22+$I22)*(1+IF($K22="N",0,INPUTS!$C$23)) -> 0 | M22: =$E22*$H22+$J22 -> 0 | N22: =$M22*IF(OR($B22="V",$B22="AC"),'LABOUR RATES'!$E$26,'LABOUR RATES'!$E$11) -> 0 | O22: =$M22*IF(OR($B22="V",$B22="AC"),'LABOUR RATES'!$C$27,'LABOUR RATES'!$C$12) -> 0 | P22: =$L22+$N22+$O22 -> 0 | Q22: =IF(OR($B22="",$C22=""),"",IFERROR(SUMIFS('KNOWIFY REVIEW'!$AF$4:$AF$400,'KNOWIFY REVIEW'!$AB$4:$AB$400,$B22,'KNOWIFY REVIEW'!$AC$4:$AC$400,$C22,'KNOWIFY REVIEW'!$AD$4:$AD$400,1)/SUMIFS('KNOWIFY REVIEW'!$AE$4:$AE$400,'KNOWIFY REVIEW'!$AB$4:$AB$400,$B22,'KNOWIFY REVIEW'!$AC$4:$AC$400,$C22,'KNOWIFY REVIEW'!$AD$4:$AD$400,1),"")) -> 1.3492499 | R22: =IF(OR($B22="",$C22=""),"",IFERROR(SUMIFS('KNOWIFY REVIEW'!$AH$4:$AH$400,'KNOWIFY REVIEW'!$AB$4:$AB$400,$B22,'KNOWIFY REVIEW'!$AC$4:$AC$400,IF(OR($C22=INPUTS!$B$69,$C22=INPUTS!$B$70),INPUTS!$B$71,$C22),'KNOWIFY REVIEW'!$AD$4:$AD$400,1)/SUMIFS('KNOWIFY REVIEW'!$AG$4:$AG$400,'KNOWIFY REVIEW'!$AB$4:$AB$400,$B22,'KNOWIFY REVIEW'!$AC$4:$AC$400,IF(OR($C22=INPUTS!$B$69,$C22=INPUTS!$B$70),INPUTS!$B$71,$C22),'KNOWIFY REVIEW'!$AD$4:$AD$400,1),"")) -> 1.2924123 | S22: =IF(MAX(N($Q22),N($R22))>1.1,"Past job ran over budget","") -> Past job ran over budget
A23: P-RI-DWD | B23: P | C23: 03 Rough-in (Labour) | D23: Domestic Water Distribution Piping | F23: lf | K23: Y | L23: =($E23*$G23+$I23)*(1+IF($K23="N",0,INPUTS!$C$23)) -> 0 | M23: =$E23*$H23+$J23 -> 0 | N23: =$M23*IF(OR($B23="V",$B23="AC"),'LABOUR RATES'!$E$26,'LABOUR RATES'!$E$11) -> 0 | O23: =$M23*IF(OR($B23="V",$B23="AC"),'LABOUR RATES'!$C$27,'LABOUR RATES'!$C$12) -> 0 | P23: =$L23+$N23+$O23 -> 0 | Q23: =IF(OR($B23="",$C23=""),"",IFERROR(SUMIFS('KNOWIFY REVIEW'!$AF$4:$AF$400,'KNOWIFY REVIEW'!$AB$4:$AB$400,$B23,'KNOWIFY REVIEW'!$AC$4:$AC$400,$C23,'KNOWIFY REVIEW'!$AD$4:$AD$400,1)/SUMIFS('KNOWIFY REVIEW'!$AE$4:$AE$400,'KNOWIFY REVIEW'!$AB$4:$AB$400,$B23,'KNOWIFY REVIEW'!$AC$4:$AC$400,$C23,'KNOWIFY REVIEW'!$AD$4:$AD$400,1),"")) -> 1.3492499 | R23: =IF(OR($B23="",$C23=""),"",IFERROR(SUMIFS('KNOWIFY REVIEW'!$AH$4:$AH$400,'KNOWIFY REVIEW'!$AB$4:$AB$400,$B23,'KNOWIFY REVIEW'!$AC$4:$AC$400,IF(OR($C23=INPUTS!$B$69,$C23=INPUTS!$B$70),INPUTS!$B$71,$C23),'KNOWIFY REVIEW'!$AD$4:$AD$400,1)/SUMIFS('KNOWIFY REVIEW'!$AG$4:$AG$400,'KNOWIFY REVIEW'!$AB$4:$AB$400,$B23,'KNOWIFY REVIEW'!$AC$4:$AC$400,IF(OR($C23=INPUTS!$B$69,$C23=INPUTS!$B$70),INPUTS!$B$71,$C23),'KNOWIFY REVIEW'!$AD$4:$AD$400,1),"")) -> 1.2924123 | S23: =IF(MAX(N($Q23),N($R23))>1.1,"Past job ran over budget","") -> Past job ran over budget
A24: P-RI-DWS | B24: P | C24: 03 Rough-in (Labour) | D24: Domestic Water Insuite Piping | E24: 123 | F24: suite | G24: 800 | H24: 12 | K24: Y | L24: =($E24*$G24+$I24)*(1+IF($K24="N",0,INPUTS!$C$23)) -> 105288 | M24: =$E24*$H24+$J24 -> 1476 | N24: =$M24*IF(OR($B24="V",$B24="AC"),'LABOUR RATES'!$E$26,'LABOUR RATES'!$E$11) -> 95563.62 | O24: =$M24*IF(OR($B24="V",$B24="AC"),'LABOUR RATES'!$C$27,'LABOUR RATES'!$C$12) -> 32472 | P24: =$L24+$N24+$O24 -> 233323.62 | Q24: =IF(OR($B24="",$C24=""),"",IFERROR(SUMIFS('KNOWIFY REVIEW'!$AF$4:$AF$400,'KNOWIFY REVIEW'!$AB$4:$AB$400,$B24,'KNOWIFY REVIEW'!$AC$4:$AC$400,$C24,'KNOWIFY REVIEW'!$AD$4:$AD$400,1)/SUMIFS('KNOWIFY REVIEW'!$AE$4:$AE$400,'KNOWIFY REVIEW'!$AB$4:$AB$400,$B24,'KNOWIFY REVIEW'!$AC$4:$AC$400,$C24,'KNOWIFY REVIEW'!$AD$4:$AD$400,1),"")) -> 1.3492499 | R24: =IF(OR($B24="",$C24=""),"",IFERROR(SUMIFS('KNOWIFY REVIEW'!$AH$4:$AH$400,'KNOWIFY REVIEW'!$AB$4:$AB$400,$B24,'KNOWIFY REVIEW'!$AC$4:$AC$400,IF(OR($C24=INPUTS!$B$69,$C24=INPUTS!$B$70),INPUTS!$B$71,$C24),'KNOWIFY REVIEW'!$AD$4:$AD$400,1)/SUMIFS('KNOWIFY REVIEW'!$AG$4:$AG$400,'KNOWIFY REVIEW'!$AB$4:$AB$400,$B24,'KNOWIFY REVIEW'!$AC$4:$AC$400,IF(OR($C24=INPUTS!$B$69,$C24=INPUTS!$B$70),INPUTS!$B$71,$C24),'KNOWIFY REVIEW'!$AD$4:$AD$400,1),"")) -> 1.2924123 | S24: =IF(MAX(N($Q24),N($R24))>1.1,"Past job ran over budget","") -> Past job ran over budget
A25: P-RI-IRR | B25: P | C25: 03 Rough-in (Labour) | D25: Irrigation | F25: LS | K25: Y | L25: =($E25*$G25+$I25)*(1+IF($K25="N",0,INPUTS!$C$23)) -> 0 | M25: =$E25*$H25+$J25 -> 0 | N25: =$M25*IF(OR($B25="V",$B25="AC"),'LABOUR RATES'!$E$26,'LABOUR RATES'!$E$11) -> 0 | O25: =$M25*IF(OR($B25="V",$B25="AC"),'LABOUR RATES'!$C$27,'LABOUR RATES'!$C$12) -> 0 | P25: =$L25+$N25+$O25 -> 0 | Q25: =IF(OR($B25="",$C25=""),"",IFERROR(SUMIFS('KNOWIFY REVIEW'!$AF$4:$AF$400,'KNOWIFY REVIEW'!$AB$4:$AB$400,$B25,'KNOWIFY REVIEW'!$AC$4:$AC$400,$C25,'KNOWIFY REVIEW'!$AD$4:$AD$400,1)/SUMIFS('KNOWIFY REVIEW'!$AE$4:$AE$400,'KNOWIFY REVIEW'!$AB$4:$AB$400,$B25,'KNOWIFY REVIEW'!$AC$4:$AC$400,$C25,'KNOWIFY REVIEW'!$AD$4:$AD$400,1),"")) -> 1.3492499 | R25: =IF(OR($B25="",$C25=""),"",IFERROR(SUMIFS('KNOWIFY REVIEW'!$AH$4:$AH$400,'KNOWIFY REVIEW'!$AB$4:$AB$400,$B25,'KNOWIFY REVIEW'!$AC$4:$AC$400,IF(OR($C25=INPUTS!$B$69,$C25=INPUTS!$B$70),INPUTS!$B$71,$C25),'KNOWIFY REVIEW'!$AD$4:$AD$400,1)/SUMIFS('KNOWIFY REVIEW'!$AG$4:$AG$400,'KNOWIFY REVIEW'!$AB$4:$AB$400,$B25,'KNOWIFY REVIEW'!$AC$4:$AC$400,IF(OR($C25=INPUTS!$B$69,$C25=INPUTS!$B$70),INPUTS!$B$71,$C25),'KNOWIFY REVIEW'!$AD$4:$AD$400,1),"")) -> 1.2924123 | S25: =IF(MAX(N($Q25),N($R25))>1.1,"Past job ran over budget","") -> Past job ran over budget
A26: P-RI-COND | B26: P | C26: 03 Rough-in (Labour) | D26: Condensate Drains (if by Plumbing) | F26: LS | K26: Y | L26: =($E26*$G26+$I26)*(1+IF($K26="N",0,INPUTS!$C$23)) -> 0 | M26: =$E26*$H26+$J26 -> 0 | N26: =$M26*IF(OR($B26="V",$B26="AC"),'LABOUR RATES'!$E$26,'LABOUR RATES'!$E$11) -> 0 | O26: =$M26*IF(OR($B26="V",$B26="AC"),'LABOUR RATES'!$C$27,'LABOUR RATES'!$C$12) -> 0 | P26: =$L26+$N26+$O26 -> 0 | Q26: =IF(OR($B26="",$C26=""),"",IFERROR(SUMIFS('KNOWIFY REVIEW'!$AF$4:$AF$400,'KNOWIFY REVIEW'!$AB$4:$AB$400,$B26,'KNOWIFY REVIEW'!$AC$4:$AC$400,$C26,'KNOWIFY REVIEW'!$AD$4:$AD$400,1)/SUMIFS('KNOWIFY REVIEW'!$AE$4:$AE$400,'KNOWIFY REVIEW'!$AB$4:$AB$400,$B26,'KNOWIFY REVIEW'!$AC$4:$AC$400,$C26,'KNOWIFY REVIEW'!$AD$4:$AD$400,1),"")) -> 1.3492499 | R26: =IF(OR($B26="",$C26=""),"",IFERROR(SUMIFS('KNOWIFY REVIEW'!$AH$4:$AH$400,'KNOWIFY REVIEW'!$AB$4:$AB$400,$B26,'KNOWIFY REVIEW'!$AC$4:$AC$400,IF(OR($C26=INPUTS!$B$69,$C26=INPUTS!$B$70),INPUTS!$B$71,$C26),'KNOWIFY REVIEW'!$AD$4:$AD$400,1)/SUMIFS('KNOWIFY REVIEW'!$AG$4:$AG$400,'KNOWIFY REVIEW'!$AB$4:$AB$400,$B26,'KNOWIFY REVIEW'!$AC$4:$AC$400,IF(OR($C26=INPUTS!$B$69,$C26=INPUTS!$B$70),INPUTS!$B$71,$C26),'KNOWIFY REVIEW'!$AD$4:$AD$400,1),"")) -> 1.2924123 | S26: =IF(MAX(N($Q26),N($R26))>1.1,"Past job ran over budget","") -> Past job ran over budget
A27: P-RI-GAS | B27: P | C27: 03 Rough-in (Labour) | D27: Gas & Boiler Vents | F27: LS | K27: Y | L27: =($E27*$G27+$I27)*(1+IF($K27="N",0,INPUTS!$C$23)) -> 0 | M27: =$E27*$H27+$J27 -> 0 | N27: =$M27*IF(OR($B27="V",$B27="AC"),'LABOUR RATES'!$E$26,'LABOUR RATES'!$E$11) -> 0 | O27: =$M27*IF(OR($B27="V",$B27="AC"),'LABOUR RATES'!$C$27,'LABOUR RATES'!$C$12) -> 0 | P27: =$L27+$N27+$O27 -> 0 | Q27: =IF(OR($B27="",$C27=""),"",IFERROR(SUMIFS('KNOWIFY REVIEW'!$AF$4:$AF$400,'KNOWIFY REVIEW'!$AB$4:$AB$400,$B27,'KNOWIFY REVIEW'!$AC$4:$AC$400,$C27,'KNOWIFY REVIEW'!$AD$4:$AD$400,1)/SUMIFS('KNOWIFY REVIEW'!$AE$4:$AE$400,'KNOWIFY REVIEW'!$AB$4:$AB$400,$B27,'KNOWIFY REVIEW'!$AC$4:$AC$400,$C27,'KNOWIFY REVIEW'!$AD$4:$AD$400,1),"")) -> 1.3492499 | R27: =IF(OR($B27="",$C27=""),"",IFERROR(SUMIFS('KNOWIFY REVIEW'!$AH$4:$AH$400,'KNOWIFY REVIEW'!$AB$4:$AB$400,$B27,'KNOWIFY REVIEW'!$AC$4:$AC$400,IF(OR($C27=INPUTS!$B$69,$C27=INPUTS!$B$70),INPUTS!$B$71,$C27),'KNOWIFY REVIEW'!$AD$4:$AD$400,1)/SUMIFS('KNOWIFY REVIEW'!$AG$4:$AG$400,'KNOWIFY REVIEW'!$AB$4:$AB$400,$B27,'KNOWIFY REVIEW'!$AC$4:$AC$400,IF(OR($C27=INPUTS!$B$69,$C27=INPUTS!$B$70),INPUTS!$B$71,$C27),'KNOWIFY REVIEW'!$AD$4:$AD$400,1),"")) -> 1.2924123 | S27: =IF(MAX(N($Q27),N($R27))>1.1,"Past job ran over budget","") -> Past job ran over budget
A28: P-RI-DRN | B28: P | C28: 03 Rough-in (Labour) | D28: Drains & Hose Bibs (rough-in) | F28: ea | K28: Y | L28: =($E28*$G28+$I28)*(1+IF($K28="N",0,INPUTS!$C$23)) -> 0 | M28: =$E28*$H28+$J28 -> 0 | N28: =$M28*IF(OR($B28="V",$B28="AC"),'LABOUR RATES'!$E$26,'LABOUR RATES'!$E$11) -> 0 | O28: =$M28*IF(OR($B28="V",$B28="AC"),'LABOUR RATES'!$C$27,'LABOUR RATES'!$C$12) -> 0 | P28: =$L28+$N28+$O28 -> 0 | Q28: =IF(OR($B28="",$C28=""),"",IFERROR(SUMIFS('KNOWIFY REVIEW'!$AF$4:$AF$400,'KNOWIFY REVIEW'!$AB$4:$AB$400,$B28,'KNOWIFY REVIEW'!$AC$4:$AC$400,$C28,'KNOWIFY REVIEW'!$AD$4:$AD$400,1)/SUMIFS('KNOWIFY REVIEW'!$AE$4:$AE$400,'KNOWIFY REVIEW'!$AB$4:$AB$400,$B28,'KNOWIFY REVIEW'!$AC$4:$AC$400,$C28,'KNOWIFY REVIEW'!$AD$4:$AD$400,1),"")) -> 1.3492499 | R28: =IF(OR($B28="",$C28=""),"",IFERROR(SUMIFS('KNOWIFY REVIEW'!$AH$4:$AH$400,'KNOWIFY REVIEW'!$AB$4:$AB$400,$B28,'KNOWIFY REVIEW'!$AC$4:$AC$400,IF(OR($C28=INPUTS!$B$69,$C28=INPUTS!$B$70),INPUTS!$B$71,$C28),'KNOWIFY REVIEW'!$AD$4:$AD$400,1)/SUMIFS('KNOWIFY REVIEW'!$AG$4:$AG$400,'KNOWIFY REVIEW'!$AB$4:$AB$400,$B28,'KNOWIFY REVIEW'!$AC$4:$AC$400,IF(OR($C28=INPUTS!$B$69,$C28=INPUTS!$B$70),INPUTS!$B$71,$C28),'KNOWIFY REVIEW'!$AD$4:$AD$400,1),"")) -> 1.2924123 | S28: =IF(MAX(N($Q28),N($R28))>1.1,"Past job ran over budget","") -> Past job ran over budget
A29: P-RI-WER | B29: P | C29: 03 Rough-in (Labour) | D29: Water Entry Room | F29: LS | K29: Y | L29: =($E29*$G29+$I29)*(1+IF($K29="N",0,INPUTS!$C$23)) -> 0 | M29: =$E29*$H29+$J29 -> 0 | N29: =$M29*IF(OR($B29="V",$B29="AC"),'LABOUR RATES'!$E$26,'LABOUR RATES'!$E$11) -> 0 | O29: =$M29*IF(OR($B29="V",$B29="AC"),'LABOUR RATES'!$C$27,'LABOUR RATES'!$C$12) -> 0 | P29: =$L29+$N29+$O29 -> 0 | Q29: =IF(OR($B29="",$C29=""),"",IFERROR(SUMIFS('KNOWIFY REVIEW'!$AF$4:$AF$400,'KNOWIFY REVIEW'!$AB$4:$AB$400,$B29,'KNOWIFY REVIEW'!$AC$4:$AC$400,$C29,'KNOWIFY REVIEW'!$AD$4:$AD$400,1)/SUMIFS('KNOWIFY REVIEW'!$AE$4:$AE$400,'KNOWIFY REVIEW'!$AB$4:$AB$400,$B29,'KNOWIFY REVIEW'!$AC$4:$AC$400,$C29,'KNOWIFY REVIEW'!$AD$4:$AD$400,1),"")) -> 1.3492499 | R29: =IF(OR($B29="",$C29=""),"",IFERROR(SUMIFS('KNOWIFY REVIEW'!$AH$4:$AH$400,'KNOWIFY REVIEW'!$AB$4:$AB$400,$B29,'KNOWIFY REVIEW'!$AC$4:$AC$400,IF(OR($C29=INPUTS!$B$69,$C29=INPUTS!$B$70),INPUTS!$B$71,$C29),'KNOWIFY REVIEW'!$AD$4:$AD$400,1)/SUMIFS('KNOWIFY REVIEW'!$AG$4:$AG$400,'KNOWIFY REVIEW'!$AB$4:$AB$400,$B29,'KNOWIFY REVIEW'!$AC$4:$AC$400,IF(OR($C29=INPUTS!$B$69,$C29=INPUTS!$B$70),INPUTS!$B$71,$C29),'KNOWIFY REVIEW'!$AD$4:$AD$400,1),"")) -> 1.2924123 | S29: =IF(MAX(N($Q29),N($R29))>1.1,"Past job ran over budget","") -> Past job ran over budget
A30: P-RI-FLSH | B30: P | C30: 03 Rough-in (Labour) | D30: Roof Flashings | F30: ea | K30: Y | L30: =($E30*$G30+$I30)*(1+IF($K30="N",0,INPUTS!$C$23)) -> 0 | M30: =$E30*$H30+$J30 -> 0 | N30: =$M30*IF(OR($B30="V",$B30="AC"),'LABOUR RATES'!$E$26,'LABOUR RATES'!$E$11) -> 0 | O30: =$M30*IF(OR($B30="V",$B30="AC"),'LABOUR RATES'!$C$27,'LABOUR RATES'!$C$12) -> 0 | P30: =$L30+$N30+$O30 -> 0 | Q30: =IF(OR($B30="",$C30=""),"",IFERROR(SUMIFS('KNOWIFY REVIEW'!$AF$4:$AF$400,'KNOWIFY REVIEW'!$AB$4:$AB$400,$B30,'KNOWIFY REVIEW'!$AC$4:$AC$400,$C30,'KNOWIFY REVIEW'!$AD$4:$AD$400,1)/SUMIFS('KNOWIFY REVIEW'!$AE$4:$AE$400,'KNOWIFY REVIEW'!$AB$4:$AB$400,$B30,'KNOWIFY REVIEW'!$AC$4:$AC$400,$C30,'KNOWIFY REVIEW'!$AD$4:$AD$400,1),"")) -> 1.3492499 | R30: =IF(OR($B30="",$C30=""),"",IFERROR(SUMIFS('KNOWIFY REVIEW'!$AH$4:$AH$400,'KNOWIFY REVIEW'!$AB$4:$AB$400,$B30,'KNOWIFY REVIEW'!$AC$4:$AC$400,IF(OR($C30=INPUTS!$B$69,$C30=INPUTS!$B$70),INPUTS!$B$71,$C30),'KNOWIFY REVIEW'!$AD$4:$AD$400,1)/SUMIFS('KNOWIFY REVIEW'!$AG$4:$AG$400,'KNOWIFY REVIEW'!$AB$4:$AB$400,$B30,'KNOWIFY REVIEW'!$AC$4:$AC$400,IF(OR($C30=INPUTS!$B$69,$C30=INPUTS!$B$70),INPUTS!$B$71,$C30),'KNOWIFY REVIEW'!$AD$4:$AD$400,1),"")) -> 1.2924123 | S30: =IF(MAX(N($Q30),N($R30))>1.1,"Past job ran over budget","") -> Past job ran over budget
A31: P-RI-CAN | B31: P | C31: 03 Rough-in (Labour) | D31: Canning / Cutting / Layout | F31: LS | K31: Y | L31: =($E31*$G31+$I31)*(1+IF($K31="N",0,INPUTS!$C$23)) -> 0 | M31: =$E31*$H31+$J31 -> 0 | N31: =$M31*IF(OR($B31="V",$B31="AC"),'LABOUR RATES'!$E$26,'LABOUR RATES'!$E$11) -> 0 | O31: =$M31*IF(OR($B31="V",$B31="AC"),'LABOUR RATES'!$C$27,'LABOUR RATES'!$C$12) -> 0 | P31: =$L31+$N31+$O31 -> 0 | Q31: =IF(OR($B31="",$C31=""),"",IFERROR(SUMIFS('KNOWIFY REVIEW'!$AF$4:$AF$400,'KNOWIFY REVIEW'!$AB$4:$AB$400,$B31,'KNOWIFY REVIEW'!$AC$4:$AC$400,$C31,'KNOWIFY REVIEW'!$AD$4:$AD$400,1)/SUMIFS('KNOWIFY REVIEW'!$AE$4:$AE$400,'KNOWIFY REVIEW'!$AB$4:$AB$400,$B31,'KNOWIFY REVIEW'!$AC$4:$AC$400,$C31,'KNOWIFY REVIEW'!$AD$4:$AD$400,1),"")) -> 1.3492499 | R31: =IF(OR($B31="",$C31=""),"",IFERROR(SUMIFS('KNOWIFY REVIEW'!$AH$4:$AH$400,'KNOWIFY REVIEW'!$AB$4:$AB$400,$B31,'KNOWIFY REVIEW'!$AC$4:$AC$400,IF(OR($C31=INPUTS!$B$69,$C31=INPUTS!$B$70),INPUTS!$B$71,$C31),'KNOWIFY REVIEW'!$AD$4:$AD$400,1)/SUMIFS('KNOWIFY REVIEW'!$AG$4:$AG$400,'KNOWIFY REVIEW'!$AB$4:$AB$400,$B31,'KNOWIFY REVIEW'!$AC$4:$AC$400,IF(OR($C31=INPUTS!$B$69,$C31=INPUTS!$B$70),INPUTS!$B$71,$C31),'KNOWIFY REVIEW'!$AD$4:$AD$400,1),"")) -> 1.2924123 | S31: =IF(MAX(N($Q31),N($R31))>1.1,"Past job ran over budget","") -> Past job ran over budget
A32: P-RI-CLN | B32: P | C32: 03 Rough-in (Labour) | D32: Clean-up | F32: LS | K32: Y | L32: =($E32*$G32+$I32)*(1+IF($K32="N",0,INPUTS!$C$23)) -> 0 | M32: =$E32*$H32+$J32 -> 0 | N32: =$M32*IF(OR($B32="V",$B32="AC"),'LABOUR RATES'!$E$26,'LABOUR RATES'!$E$11) -> 0 | O32: =$M32*IF(OR($B32="V",$B32="AC"),'LABOUR RATES'!$C$27,'LABOUR RATES'!$C$12) -> 0 | P32: =$L32+$N32+$O32 -> 0 | Q32: =IF(OR($B32="",$C32=""),"",IFERROR(SUMIFS('KNOWIFY REVIEW'!$AF$4:$AF$400,'KNOWIFY REVIEW'!$AB$4:$AB$400,$B32,'KNOWIFY REVIEW'!$AC$4:$AC$400,$C32,'KNOWIFY REVIEW'!$AD$4:$AD$400,1)/SUMIFS('KNOWIFY REVIEW'!$AE$4:$AE$400,'KNOWIFY REVIEW'!$AB$4:$AB$400,$B32,'KNOWIFY REVIEW'!$AC$4:$AC$400,$C32,'KNOWIFY REVIEW'!$AD$4:$AD$400,1),"")) -> 1.3492499 | R32: =IF(OR($B32="",$C32=""),"",IFERROR(SUMIFS('KNOWIFY REVIEW'!$AH$4:$AH$400,'KNOWIFY REVIEW'!$AB$4:$AB$400,$B32,'KNOWIFY REVIEW'!$AC$4:$AC$400,IF(OR($C32=INPUTS!$B$69,$C32=INPUTS!$B$70),INPUTS!$B$71,$C32),'KNOWIFY REVIEW'!$AD$4:$AD$400,1)/SUMIFS('KNOWIFY REVIEW'!$AG$4:$AG$400,'KNOWIFY REVIEW'!$AB$4:$AB$400,$B32,'KNOWIFY REVIEW'!$AC$4:$AC$400,IF(OR($C32=INPUTS!$B$69,$C32=INPUTS!$B$70),INPUTS!$B$71,$C32),'KNOWIFY REVIEW'!$AD$4:$AD$400,1),"")) -> 1.2924123 | S32: =IF(MAX(N($Q32),N($R32))>1.1,"Past job ran over budget","") -> Past job ran over budget
A33: P-FN-FIX | B33: P | C33: 04 Finishing (Labour) | D33: Set Plumbing Fixtures | F33: ea | K33: Y | L33: =($E33*$G33+$I33)*(1+IF($K33="N",0,INPUTS!$C$23)) -> 0 | M33: =$E33*$H33+$J33 -> 0 | N33: =$M33*IF(OR($B33="V",$B33="AC"),'LABOUR RATES'!$E$26,'LABOUR RATES'!$E$11) -> 0 | O33: =$M33*IF(OR($B33="V",$B33="AC"),'LABOUR RATES'!$C$27,'LABOUR RATES'!$C$12) -> 0 | P33: =$L33+$N33+$O33 -> 0 | Q33: =IF(OR($B33="",$C33=""),"",IFERROR(SUMIFS('KNOWIFY REVIEW'!$AF$4:$AF$400,'KNOWIFY REVIEW'!$AB$4:$AB$400,$B33,'KNOWIFY REVIEW'!$AC$4:$AC$400,$C33,'KNOWIFY REVIEW'!$AD$4:$AD$400,1)/SUMIFS('KNOWIFY REVIEW'!$AE$4:$AE$400,'KNOWIFY REVIEW'!$AB$4:$AB$400,$B33,'KNOWIFY REVIEW'!$AC$4:$AC$400,$C33,'KNOWIFY REVIEW'!$AD$4:$AD$400,1),"")) | R33: =IF(OR($B33="",$C33=""),"",IFERROR(SUMIFS('KNOWIFY REVIEW'!$AH$4:$AH$400,'KNOWIFY REVIEW'!$AB$4:$AB$400,$B33,'KNOWIFY REVIEW'!$AC$4:$AC$400,IF(OR($C33=INPUTS!$B$69,$C33=INPUTS!$B$70),INPUTS!$B$71,$C33),'KNOWIFY REVIEW'!$AD$4:$AD$400,1)/SUMIFS('KNOWIFY REVIEW'!$AG$4:$AG$400,'KNOWIFY REVIEW'!$AB$4:$AB$400,$B33,'KNOWIFY REVIEW'!$AC$4:$AC$400,IF(OR($C33=INPUTS!$B$69,$C33=INPUTS!$B$70),INPUTS!$B$71,$C33),'KNOWIFY REVIEW'!$AD$4:$AD$400,1),"")) -> 1.2924123 | S33: =IF(MAX(N($Q33),N($R33))>1.1,"Past job ran over budget","") -> Past job ran over budget
A34: P-FN-AP | B34: P | C34: 04 Finishing (Labour) | D34: Install Access Panels | F34: ea | K34: Y | L34: =($E34*$G34+$I34)*(1+IF($K34="N",0,INPUTS!$C$23)) -> 0 | M34: =$E34*$H34+$J34 -> 0 | N34: =$M34*IF(OR($B34="V",$B34="AC"),'LABOUR RATES'!$E$26,'LABOUR RATES'!$E$11) -> 0 | O34: =$M34*IF(OR($B34="V",$B34="AC"),'LABOUR RATES'!$C$27,'LABOUR RATES'!$C$12) -> 0 | P34: =$L34+$N34+$O34 -> 0 | Q34: =IF(OR($B34="",$C34=""),"",IFERROR(SUMIFS('KNOWIFY REVIEW'!$AF$4:$AF$400,'KNOWIFY REVIEW'!$AB$4:$AB$400,$B34,'KNOWIFY REVIEW'!$AC$4:$AC$400,$C34,'KNOWIFY REVIEW'!$AD$4:$AD$400,1)/SUMIFS('KNOWIFY REVIEW'!$AE$4:$AE$400,'KNOWIFY REVIEW'!$AB$4:$AB$400,$B34,'KNOWIFY REVIEW'!$AC$4:$AC$400,$C34,'KNOWIFY REVIEW'!$AD$4:$AD$400,1),"")) | R34: =IF(OR($B34="",$C34=""),"",IFERROR(SUMIFS('KNOWIFY REVIEW'!$AH$4:$AH$400,'KNOWIFY REVIEW'!$AB$4:$AB$400,$B34,'KNOWIFY REVIEW'!$AC$4:$AC$400,IF(OR($C34=INPUTS!$B$69,$C34=INPUTS!$B$70),INPUTS!$B$71,$C34),'KNOWIFY REVIEW'!$AD$4:$AD$400,1)/SUMIFS('KNOWIFY REVIEW'!$AG$4:$AG$400,'KNOWIFY REVIEW'!$AB$4:$AB$400,$B34,'KNOWIFY REVIEW'!$AC$4:$AC$400,IF(OR($C34=INPUTS!$B$69,$C34=INPUTS!$B$70),INPUTS!$B$71,$C34),'KNOWIFY REVIEW'!$AD$4:$AD$400,1),"")) -> 1.2924123 | S34: =IF(MAX(N($Q34),N($R34))>1.1,"Past job ran over budget","") -> Past job ran over budget
A35: P-FN-LBL | B35: P | C35: 04 Finishing (Labour) | D35: Pipe Labelling | F35: LS | K35: Y | L35: =($E35*$G35+$I35)*(1+IF($K35="N",0,INPUTS!$C$23)) -> 0 | M35: =$E35*$H35+$J35 -> 0 | N35: =$M35*IF(OR($B35="V",$B35="AC"),'LABOUR RATES'!$E$26,'LABOUR RATES'!$E$11) -> 0 | O35: =$M35*IF(OR($B35="V",$B35="AC"),'LABOUR RATES'!$C$27,'LABOUR RATES'!$C$12) -> 0 | P35: =$L35+$N35+$O35 -> 0 | Q35: =IF(OR($B35="",$C35=""),"",IFERROR(SUMIFS('KNOWIFY REVIEW'!$AF$4:$AF$400,'KNOWIFY REVIEW'!$AB$4:$AB$400,$B35,'KNOWIFY REVIEW'!$AC$4:$AC$400,$C35,'KNOWIFY REVIEW'!$AD$4:$AD$400,1)/SUMIFS('KNOWIFY REVIEW'!$AE$4:$AE$400,'KNOWIFY REVIEW'!$AB$4:$AB$400,$B35,'KNOWIFY REVIEW'!$AC$4:$AC$400,$C35,'KNOWIFY REVIEW'!$AD$4:$AD$400,1),"")) | R35: =IF(OR($B35="",$C35=""),"",IFERROR(SUMIFS('KNOWIFY REVIEW'!$AH$4:$AH$400,'KNOWIFY REVIEW'!$AB$4:$AB$400,$B35,'KNOWIFY REVIEW'!$AC$4:$AC$400,IF(OR($C35=INPUTS!$B$69,$C35=INPUTS!$B$70),INPUTS!$B$71,$C35),'KNOWIFY REVIEW'!$AD$4:$AD$400,1)/SUMIFS('KNOWIFY REVIEW'!$AG$4:$AG$400,'KNOWIFY REVIEW'!$AB$4:$AB$400,$B35,'KNOWIFY REVIEW'!$AC$4:$AC$400,IF(OR($C35=INPUTS!$B$69,$C35=INPUTS!$B$70),INPUTS!$B$71,$C35),'KNOWIFY REVIEW'!$AD$4:$AD$400,1),"")) -> 1.2924123 | S35: =IF(MAX(N($Q35),N($R35))>1.1,"Past job ran over budget","") -> Past job ran over budget
A36: P-EQ-FIX | B36: P | C36: 06 Fixtures & Equipment Supply | D36: Plumbing Fixtures & Access Panels Supply | F36: LS | K36: Y | L36: =($E36*$G36+$I36)*(1+IF($K36="N",0,INPUTS!$C$23)) -> 0 | M36: =$E36*$H36+$J36 -> 0 | N36: =$M36*IF(OR($B36="V",$B36="AC"),'LABOUR RATES'!$E$26,'LABOUR RATES'!$E$11) -> 0 | O36: =$M36*IF(OR($B36="V",$B36="AC"),'LABOUR RATES'!$C$27,'LABOUR RATES'!$C$12) -> 0 | P36: =$L36+$N36+$O36 -> 0 | Q36: =IF(OR($B36="",$C36=""),"",IFERROR(SUMIFS('KNOWIFY REVIEW'!$AF$4:$AF$400,'KNOWIFY REVIEW'!$AB$4:$AB$400,$B36,'KNOWIFY REVIEW'!$AC$4:$AC$400,$C36,'KNOWIFY REVIEW'!$AD$4:$AD$400,1)/SUMIFS('KNOWIFY REVIEW'!$AE$4:$AE$400,'KNOWIFY REVIEW'!$AB$4:$AB$400,$B36,'KNOWIFY REVIEW'!$AC$4:$AC$400,$C36,'KNOWIFY REVIEW'!$AD$4:$AD$400,1),"")) | R36: =IF(OR($B36="",$C36=""),"",IFERROR(SUMIFS('KNOWIFY REVIEW'!$AH$4:$AH$400,'KNOWIFY REVIEW'!$AB$4:$AB$400,$B36,'KNOWIFY REVIEW'!$AC$4:$AC$400,IF(OR($C36=INPUTS!$B$69,$C36=INPUTS!$B$70),INPUTS!$B$71,$C36),'KNOWIFY REVIEW'!$AD$4:$AD$400,1)/SUMIFS('KNOWIFY REVIEW'!$AG$4:$AG$400,'KNOWIFY REVIEW'!$AB$4:$AB$400,$B36,'KNOWIFY REVIEW'!$AC$4:$AC$400,IF(OR($C36=INPUTS!$B$69,$C36=INPUTS!$B$70),INPUTS!$B$71,$C36),'KNOWIFY REVIEW'!$AD$4:$AD$400,1),"")) | S36: =IF(MAX(N($Q36),N($R36))>1.1,"Past job ran over budget","")
... A43: H-RI-MAN | B43: H | C43: 03 Rough-in (Labour) | D43: Manifolds | F43: ea | K43: Y | L43: =($E43*$G43+$I43)*(1+IF($K43="N",0,INPUTS!$C$23)) -> 0 | M43: =$E43*$H43+$J43 -> 0 | N43: =$M43*IF(OR($B43="V",$B43="AC"),'LABOUR RATES'!$E$26,'LABOUR RATES'!$E$11) -> 0 | O43: =$M43*IF(OR($B43="V",$B43="AC"),'LABOUR RATES'!$C$27,'LABOUR RATES'!$C$12) -> 0 | P43: =$L43+$N43+$O43 -> 0 | Q43: =IF(OR($B43="",$C43=""),"",IFERROR(SUMIFS('KNOWIFY REVIEW'!$AF$4:$AF$400,'KNOWIFY REVIEW'!$AB$4:$AB$400,$B43,'KNOWIFY REVIEW'!$AC$4:$AC$400,$C43,'KNOWIFY REVIEW'!$AD$4:$AD$400,1)/SUMIFS('KNOWIFY REVIEW'!$AE$4:$AE$400,'KNOWIFY REVIEW'!$AB$4:$AB$400,$B43,'KNOWIFY REVIEW'!$AC$4:$AC$400,$C43,'KNOWIFY REVIEW'!$AD$4:$AD$400,1),"")) | R43: =IF(OR($B43="",$C43=""),"",IFERROR(SUMIFS('KNOWIFY REVIEW'!$AH$4:$AH$400,'KNOWIFY REVIEW'!$AB$4:$AB$400,$B43,'KNOWIFY REVIEW'!$AC$4:$AC$400,IF(OR($C43=INPUTS!$B$69,$C43=INPUTS!$B$70),INPUTS!$B$71,$C43),'KNOWIFY REVIEW'!$AD$4:$AD$400,1)/SUMIFS('KNOWIFY REVIEW'!$AG$4:$AG$400,'KNOWIFY REVIEW'!$AB$4:$AB$400,$B43,'KNOWIFY REVIEW'!$AC$4:$AC$400,IF(OR($C43=INPUTS!$B$69,$C43=INPUTS!$B$70),INPUTS!$B$71,$C43),'KNOWIFY REVIEW'!$AD$4:$AD$400,1),"")) | S43: =IF(MAX(N($Q43),N($R43))>1.1,"Past job ran over budget","")
A44: H-RI-SUITE | B44: H | C44: 03 Rough-in (Labour) | D44: Hydronic Insuite Piping | F44: suite | H44: 8 | K44: Y | L44: =($E44*$G44+$I44)*(1+IF($K44="N",0,INPUTS!$C$23)) -> 0 | M44: =$E44*$H44+$J44 -> 0 | N44: =$M44*IF(OR($B44="V",$B44="AC"),'LABOUR RATES'!$E$26,'LABOUR RATES'!$E$11) -> 0 | O44: =$M44*IF(OR($B44="V",$B44="AC"),'LABOUR RATES'!$C$27,'LABOUR RATES'!$C$12) -> 0 | P44: =$L44+$N44+$O44 -> 0 | Q44: =IF(OR($B44="",$C44=""),"",IFERROR(SUMIFS('KNOWIFY REVIEW'!$AF$4:$AF$400,'KNOWIFY REVIEW'!$AB$4:$AB$400,$B44,'KNOWIFY REVIEW'!$AC$4:$AC$400,$C44,'KNOWIFY REVIEW'!$AD$4:$AD$400,1)/SUMIFS('KNOWIFY REVIEW'!$AE$4:$AE$400,'KNOWIFY REVIEW'!$AB$4:$AB$400,$B44,'KNOWIFY REVIEW'!$AC$4:$AC$400,$C44,'KNOWIFY REVIEW'!$AD$4:$AD$400,1),"")) | R44: =IF(OR($B44="",$C44=""),"",IFERROR(SUMIFS('KNOWIFY REVIEW'!$AH$4:$AH$400,'KNOWIFY REVIEW'!$AB$4:$AB$400,$B44,'KNOWIFY REVIEW'!$AC$4:$AC$400,IF(OR($C44=INPUTS!$B$69,$C44=INPUTS!$B$70),INPUTS!$B$71,$C44),'KNOWIFY REVIEW'!$AD$4:$AD$400,1)/SUMIFS('KNOWIFY REVIEW'!$AG$4:$AG$400,'KNOWIFY REVIEW'!$AB$4:$AB$400,$B44,'KNOWIFY REVIEW'!$AC$4:$AC$400,IF(OR($C44=INPUTS!$B$69,$C44=INPUTS!$B$70),INPUTS!$B$71,$C44),'KNOWIFY REVIEW'!$AD$4:$AD$400,1),"")) | S44: =IF(MAX(N($Q44),N($R44))>1.1,"Past job ran over budget","")
A45: H-RI-GLY | B45: H | C45: 03 Rough-in (Labour) | D45: Glycol Loop | F45: LS | K45: Y | L45: =($E45*$G45+$I45)*(1+IF($K45="N",0,INPUTS!$C$23)) -> 0 | M45: =$E45*$H45+$J45 -> 0 | N45: =$M45*IF(OR($B45="V",$B45="AC"),'LABOUR RATES'!$E$26,'LABOUR RATES'!$E$11) -> 0 | O45: =$M45*IF(OR($B45="V",$B45="AC"),'LABOUR RATES'!$C$27,'LABOUR RATES'!$C$12) -> 0 | P45: =$L45+$N45+$O45 -> 0 | Q45: =IF(OR($B45="",$C45=""),"",IFERROR(SUMIFS('KNOWIFY REVIEW'!$AF$4:$AF$400,'KNOWIFY REVIEW'!$AB$4:$AB$400,$B45,'KNOWIFY REVIEW'!$AC$4:$AC$400,$C45,'KNOWIFY REVIEW'!$AD$4:$AD$400,1)/SUMIFS('KNOWIFY REVIEW'!$AE$4:$AE$400,'KNOWIFY REVIEW'!$AB$4:$AB$400,$B45,'KNOWIFY REVIEW'!$AC$4:$AC$400,$C45,'KNOWIFY REVIEW'!$AD$4:$AD$400,1),"")) | R45: =IF(OR($B45="",$C45=""),"",IFERROR(SUMIFS('KNOWIFY REVIEW'!$AH$4:$AH$400,'KNOWIFY REVIEW'!$AB$4:$AB$400,$B45,'KNOWIFY REVIEW'!$AC$4:$AC$400,IF(OR($C45=INPUTS!$B$69,$C45=INPUTS!$B$70),INPUTS!$B$71,$C45),'KNOWIFY REVIEW'!$AD$4:$AD$400,1)/SUMIFS('KNOWIFY REVIEW'!$AG$4:$AG$400,'KNOWIFY REVIEW'!$AB$4:$AB$400,$B45,'KNOWIFY REVIEW'!$AC$4:$AC$400,IF(OR($C45=INPUTS!$B$69,$C45=INPUTS!$B$70),INPUTS!$B$71,$C45),'KNOWIFY REVIEW'!$AD$4:$AD$400,1),"")) | S45: =IF(MAX(N($Q45),N($R45))>1.1,"Past job ran over budget","")
A46: H-RI-CAN | B46: H | C46: 03 Rough-in (Labour) | D46: Canning / Cutting / Layout | F46: LS | K46: Y | L46: =($E46*$G46+$I46)*(1+IF($K46="N",0,INPUTS!$C$23)) -> 0 | M46: =$E46*$H46+$J46 -> 0 | N46: =$M46*IF(OR($B46="V",$B46="AC"),'LABOUR RATES'!$E$26,'LABOUR RATES'!$E$11) -> 0 | O46: =$M46*IF(OR($B46="V",$B46="AC"),'LABOUR RATES'!$C$27,'LABOUR RATES'!$C$12) -> 0 | P46: =$L46+$N46+$O46 -> 0 | Q46: =IF(OR($B46="",$C46=""),"",IFERROR(SUMIFS('KNOWIFY REVIEW'!$AF$4:$AF$400,'KNOWIFY REVIEW'!$AB$4:$AB$400,$B46,'KNOWIFY REVIEW'!$AC$4:$AC$400,$C46,'KNOWIFY REVIEW'!$AD$4:$AD$400,1)/SUMIFS('KNOWIFY REVIEW'!$AE$4:$AE$400,'KNOWIFY REVIEW'!$AB$4:$AB$400,$B46,'KNOWIFY REVIEW'!$AC$4:$AC$400,$C46,'KNOWIFY REVIEW'!$AD$4:$AD$400,1),"")) | R46: =IF(OR($B46="",$C46=""),"",IFERROR(SUMIFS('KNOWIFY REVIEW'!$AH$4:$AH$400,'KNOWIFY REVIEW'!$AB$4:$AB$400,$B46,'KNOWIFY REVIEW'!$AC$4:$AC$400,IF(OR($C46=INPUTS!$B$69,$C46=INPUTS!$B$70),INPUTS!$B$71,$C46),'KNOWIFY REVIEW'!$AD$4:$AD$400,1)/SUMIFS('KNOWIFY REVIEW'!$AG$4:$AG$400,'KNOWIFY REVIEW'!$AB$4:$AB$400,$B46,'KNOWIFY REVIEW'!$AC$4:$AC$400,IF(OR($C46=INPUTS!$B$69,$C46=INPUTS!$B$70),INPUTS!$B$71,$C46),'KNOWIFY REVIEW'!$AD$4:$AD$400,1),"")) | S46: =IF(MAX(N($Q46),N($R46))>1.1,"Past job ran over budget","")
A47: H-RI-CLN | B47: H | C47: 03 Rough-in (Labour) | D47: Clean-up | F47: LS | K47: Y | L47: =($E47*$G47+$I47)*(1+IF($K47="N",0,INPUTS!$C$23)) -> 0 | M47: =$E47*$H47+$J47 -> 0 | N47: =$M47*IF(OR($B47="V",$B47="AC"),'LABOUR RATES'!$E$26,'LABOUR RATES'!$E$11) -> 0 | O47: =$M47*IF(OR($B47="V",$B47="AC"),'LABOUR RATES'!$C$27,'LABOUR RATES'!$C$12) -> 0 | P47: =$L47+$N47+$O47 -> 0 | Q47: =IF(OR($B47="",$C47=""),"",IFERROR(SUMIFS('KNOWIFY REVIEW'!$AF$4:$AF$400,'KNOWIFY REVIEW'!$AB$4:$AB$400,$B47,'KNOWIFY REVIEW'!$AC$4:$AC$400,$C47,'KNOWIFY REVIEW'!$AD$4:$AD$400,1)/SUMIFS('KNOWIFY REVIEW'!$AE$4:$AE$400,'KNOWIFY REVIEW'!$AB$4:$AB$400,$B47,'KNOWIFY REVIEW'!$AC$4:$AC$400,$C47,'KNOWIFY REVIEW'!$AD$4:$AD$400,1),"")) | R47: =IF(OR($B47="",$C47=""),"",IFERROR(SUMIFS('KNOWIFY REVIEW'!$AH$4:$AH$400,'KNOWIFY REVIEW'!$AB$4:$AB$400,$B47,'KNOWIFY REVIEW'!$AC$4:$AC$400,IF(OR($C47=INPUTS!$B$69,$C47=INPUTS!$B$70),INPUTS!$B$71,$C47),'KNOWIFY REVIEW'!$AD$4:$AD$400,1)/SUMIFS('KNOWIFY REVIEW'!$AG$4:$AG$400,'KNOWIFY REVIEW'!$AB$4:$AB$400,$B47,'KNOWIFY REVIEW'!$AC$4:$AC$400,IF(OR($C47=INPUTS!$B$69,$C47=INPUTS!$B$70),INPUTS!$B$71,$C47),'KNOWIFY REVIEW'!$AD$4:$AD$400,1),"")) | S47: =IF(MAX(N($Q47),N($R47))>1.1,"Past job ran over budget","")
...

Sheet HVAC EST
A1: HVAC EST
A2: Ventilation (V) and Air Conditioning (AC). Identical columns and formulas to PLUMBING EST.
A3: TOTALS | L3: =SUM(L7:L156) -> 0 | M3: =SUM(M7:M156) -> 0 | N3: =SUM(N7:N156) -> 0 | O3: =SUM(O7:O156) -> 0 | P3: =SUM(P7:P156) -> 0
